Workbook

Sheet Treatment Record
A1: Date of referal | B1: Route | C1: IP.NO | D1: Name | E1: Age | F1: Children | G1: Sex | H1: Detail Diagnosis | I1: Category | J1: Very Weak | K1: Weak | L1: Fair | M1: Stable | N1: New pts | O1: Reviews | P1: Old pts | Q1: Consultation | R1: Diagnositic Investigation | S1: Chemotharpy | T1: Radiotherapy | U1: Biopsy | V1: Scan | W1: X-ray | X1: Surgery | Y1: Medicine | Z1: Other Treatmt | AA1: Up keep | AB1: Histology | AC1: Transport | AD1: RIP | AE1: No. of days on program | AF1: Discharge | AG1: Directions
A2: 15/10/2024 | B2: Kiyunga | C2: 410/24 | D2: Nzala Joyce | E2: 34 | G2: F | H2: CaCx | I2: Ca | L2: 1 | P2: 1 | AA2: 1
A3: 15/01/2024 | B3: Kaliro | C3: 506/23 | D3: Mirembe Mariam | E3: 39 | G3: F | H3: Ca Breast | I3: Ca | L3: 1 | P3: 1 | AC3: 1
A4: 21/10/2024 | B4: Nawanyago | C4: 740/24 | D4: Kasubo Monica | E4: 50 | G4: F | H4: CaCx+HIV/AIDS | I4: Ca/HIV | L4: 1 | P4: 1 | T4: 1 | Y4: 1
A5: 45717 | B5: Bugiri | C5: 411/24 | D5: Nabwire Juliet | E5: 50 | G5: F | H5: CaCx | I5: Ca | L5: 1 | N5: 1 | T5: 1
A6: 24/01/2021 | B6: Busedde | C6: 0185/21 | D6: Kasadha Awali | E6: 65 | G6: M | H6: Endemic KS | I6: Ca | M6: 1 | P6: 1 | Y6: 1 | AC6: 1
A7: 14/3/2024 | B7: Ivukula | C7: 103/23 | D7: Ndifuna Gerald | E7: 3 | F7: 1 | G7: M | H7: Retinoblastoma | I7: Ca | M7: 1 | P7: 1 | AC7: 1
A8: 45717 | B8: Buyende | C8: 757/24 | D8: Maluliku Ntebe | E8: 4 | F8: 1 | G8: M | H8: Neuroblastoma | I8: Ca | L8: 1 | N8: 1 | U8: 1 | Y8: 1
A9: 24/5/2021 | B9: Busembatia | C9: 21/20 | D9: Nandago Hadijah | E9: 45 | G9: F | H9: Ca Breast | I9: Ca | L9: 1 | P9: 1 | Y9: 1 | AC9: 1
A10: 16/9/2024 | B10: Kidera | C10: 724/24 | D10: Muwanguzi Timothy | E10: 17 | F10: 1 | G10: M | H10: Rhabdomyosarcoma | I10: Ca | M10: 1 | P10: 1 | V10: 1 | AA10: 1 | AC10: 1
A11: 16/12/2024 | B11: Kaliro | C11: 502/24 | D11: Musa Paul | E11: 2.5 | F11: 1 | G11: M | H11: Nephroblastoma | I11: Ca | L11: 1 | P11: 1 | R11: 1 | V11: 1 | Y11: 1 | AC11: 1
A12: 25/8/2023 | B12: Busembatia | C12: 313/23 | D12: Ganyiriba Gorreti | E12: 36 | G12: F | H12: Ca Breast | I12: Ca | K12: 1 | P12: 1 | AC12: 1
A13: 45992 | B13: Kiyunga | C13: 410/23 | D13: Byabona Mirabu | E13: 60 | G13: F | H13: CaCx | I13: Ca | L13: 1 | N13: 1 | T13: 1
A14: 45445 | B14: Kayunga | C14: 041/24 | D14: Nantale Rebecca | E14: 37 | G14: F | H14: Ca Breast | I14: Ca | K14: 1 | P14: 1 | R14: 1 | U14: 1 | V14: 1 | Y14: 1
A15: 20/1/2025 | B15: Bugaya | C15: 753/24 | D15: Namabilo Nayiga Aidha | E15: 50 | G15: F | H15: CaCx | I15: Ca | L15: 1 | N15: 1 | R15: 1 | T15: 1 | V15: 1 | W15: 1
A16: 27/11/2023 | B16: Nawanyago | C16: 0643/23 | D16: Atuhaire Lilian | E16: 35 | G16: F | H16: Ca Breast | I16: Ca | L16: 1 | P16: 1 | V16: 1 | Y16: 1
A17: 45058 | B17: Kagulu | C17: 0525/23 | D17: Lubale Tom | E17: 40 | G17: M | H17: Melanoma | I17: Ca | L17: 1 | P17: 1 | AA17: 1
A18: 45172 | B18: Hospice | C18: 093/23 | D18: Alitra Alexandria | E18: 47 | G18: M | H18: Ca Thyroid | I18: Ca | L18: 1 | P18: 1 | V18: 1 | Y18: 1
A19: 45870 | B19: Lumino | C19: 275/23 | D19: Nerima Margrete | E19: 60 | G19: M | H19: Ca Breast | I19: Ca | L19: 1 | N19: 1 | R19: 1 | V19: 1 | W19: 1
A20: 18/8/2020 | B20: Hospice | C20: 118/20 | D20: Muyanga Florence | E20: 41 | G20: F | H20: Ca Breast | I20: Ca | M20: 1 | P20: 1 | V20: 1 | Y20: 1
A21: 21/11/2022 | B21: Namayingo | C21: 476/21 | D21: Kyakuwaire Teopista | E21: 41 | G21: F | H21: Ca Breast | I21: Ca | M21: 1 | P21: 1 | Y21: 1 | AC21: 1
A22: 22/11/2023 | B22: Muterere | C22: 468/23 | D22: Namirimwe Shaluwa | E22: 27 | G22: F | H22: Ca Breast | I22: Ca | L22: 1 | P22: 1 | Y22: 1 | AA22: 1 | AC22: 1
A23: 17/1/2025 | B23: Nyenga | C23: 496/24 | D23: Akudo Hellen | E23: 34 | G23: F | H23: Ca Breast | I23: Ca | L23: 1 | N23: 1 | T23: 1 | Y23: 1
A24: 19/9/2024 | B24: Kiyindi | C24: 255/24 | D24: Kikomeko Ayub | E24: 67 | G24: M | H24: Ca Oesophagus | I24: Ca | K24: 1 | P24: 1 | R24: 1 | Y24: 1 | AD24: 1
A25: 19/8/2024 | B25: Mbulamuti | C25: 650/24 | D25: Ataliba Shalom | E25: 3 | F25: 1 | G25: F | H25: Retinoblastoma | I25: Ca | L25: 1 | P25: 1 | Y25: 1 | AA25: 1 | AC25: 1
A26: 45870 | B26: Mayuge | C26: 441/24 | D26: Kyewalyanga Betty | E26: 67 | G26: F | H26: Lung Adenocarcinoma | I26: Ca | L26: 1 | N26: 1 | AC26: 1
A27: 20/11/2024 | B27: Buwenge | C27: 462/24 | D27: Achen Riana | E27: 5 | F27: 1 | G27: F | H27: Neuroblastoma | I27: Ca | K27: 1 | P27: 1 | Y27: 1 | AD27: 1 | AF27: 1
A28: 13/6/2024 | B28: Busembatia | C28: 191/24 | D28: Naigembe Juliet | E28: 38 | G28: F | H28: CaCx | I28: Ca | L28: 1 | P28: 1 | Y28: 1
A29: 45177 | B29: Kidera | C29: 324/23 | D29: Mutesi Hellen | E29: 52 | G29: F | H29: Ca Nose | I29: Ca | L29: 1 | P29: 1 | Y29: 1
A30: 16/8/2024 | B30: Budondo | C30: 322/23 | D30: Kintu Aggrey | E30: 64 | G30: M | H30: Ca Prostate | I30: Ca | L30: 1 | P30: 1 | Y30: 1
A31: 45115 | B31: Namayingo | C31: 228/23 | D31: Erumbi Kasifa | E31: 32 | G31: F | H31: Fibrosarcoma | I31: Ca | L31: 1 | P31: 1 | Y31: 1
A32: 25/10/2024 | B32: Budondo | C32: 408/24 | D32: Nabudde Aisha | E32: 26 | G32: F | H32: Ca Breast | I32: Ca | L32: 1 | P32: 1 | Y32: 1
A33: 29/4/2024 | B33: Bugembe | C33: 113/24 | D33: Namugaaju Bernadette | E33: 56 | G33: F | H33: Lymphoma | I33: Ca | M33: 1 | P33: 1 | Y33: 1
A34: 45574 | B34: Budondo | C34: 451/23 | D34: Nankabirwa Rosemary | E34: 50 | G34: F | H34: Ca Rectum | I34: Ca | L34: 1 | P34: 1 | Y34: 1
A35: 45748 | B35: Iganga | C35: 398/24 | D35: Namulinda Florence | E35: 55 | G35: F | H35: Ca Oesophagus | I35: Ca | L35: 1 | N35: 1 | Y35: 1
A36: 13/8/2024 | B36: Buyende | C36: 714/24 | D36: Musana Joseph | E36: 60 | G36: M | H36: Endemic KS | I36: Ca | L36: 1 | P36: 1 | Y36: 1
A37: 21/6/2023 | B37: Buwenge | C37: 260/23 | D37: Takoze John | E37: 57 | G37: M | H37: Ca Prostate | I37: Ca | L37: 1 | P37: 1 | Y37: 1
A38: 23/1/2024 | B38: Kamuli | C38: 613/24 | D38: Mukyala Hellen | E38: 20 | G38: F | H38: Endemic KS | I38: Ca | L38: 1 | P38: 1 | Y38: 1
A39: 29/9/2022 | B39: Kamuli | C39: 0391/21 | D39: Isabirye Sulaiman | E39: 74 | G39: M | H39: Ca Prostate | I39: Ca | L39: 1 | P39: 1 | Y39: 1
A40: 45870 | B40: Namasagali | C40: 746/24 | D40: Nampuli Monica | E40: 31 | G40: F | H40: Ca Breast | I40: Ca | L40: 1 | N40: 1 | Y40: 1
...

Sheet Treatment Data
A1: Date of referal | B1: Route | C1: IP.NO | D1: Name | E1: Age | F1: Children | G1: Sex | H1: Detail Diagnosis | I1: Category | J1: Very Weak | K1: Weak | L1: Fair | M1: Stable | N1: New pts | O1: Reviews | P1: Old pts | Q1: Consultation | R1: Diagnositic Investigation | S1: Chemotharpy | T1: Radiotherapy | U1: Biopsy | V1: Scan | W1: X-ray | X1: Surgery | Y1: Medicine | Z1: Other Treatmt | AA1: Up keep | AB1: Histology | AC1: Transport | AD1: RIP | AE1: No. of days on program | AF1: Discharge | AG1: Directions
A2: 15/10/2024 | B2: Kiyunga | C2: 410/24 | D2: Nzala Joyce | E2: 34 | G2: F | H2: CaCx | I2: Ca | L2: 1 | P2: 1 | AA2: 1
A3: 15/01/2024 | B3: Kaliro | C3: 506/23 | D3: Mirembe Mariam | E3: 39 | G3: F | H3: Ca Breast | I3: Ca | L3: 1 | P3: 1 | AC3: 1
A4: 21/10/2024 | B4: Nawanyago | C4: 740/24 | D4: Kasubo Monica | E4: 50 | G4: F | H4: CaCx+HIV/AIDS | I4: Ca/HIV | L4: 1 | P4: 1 | T4: 1 | Y4: 1
A5: 45717 | B5: Bugiri | C5: 411/24 | D5: Nabwire Juliet | E5: 50 | G5: F | H5: CaCx | I5: Ca | L5: 1 | N5: 1 | T5: 1
A6: 24/01/2021 | B6: Busedde | C6: 0185/21 | D6: Kasadha Awali | E6: 65 | G6: M | H6: Endemic KS | I6: Ca | M6: 1 | P6: 1 | Y6: 1 | AC6: 1
A7: 14/3/2024 | B7: Ivukula | C7: 103/23 | D7: Ndifuna Gerald | E7: 3 | F7: 1 | G7: M | H7: Retinoblastoma | I7: Ca | M7: 1 | P7: 1 | AC7: 1
A8: 45717 | B8: Buyende | C8: 757/24 | D8: Maluliku Ntebe | E8: 4 | F8: 1 | G8: M | H8: Neuroblastoma | I8: Ca | L8: 1 | N8: 1 | U8: 1 | Y8: 1
A9: 24/5/2021 | B9: Busembatia | C9: 21/20 | D9: Nandago Hadijah | E9: 45 | G9: F | H9: Ca Breast | I9: Ca | L9: 1 | P9: 1 | Y9: 1 | AC9: 1
A10: 16/9/2024 | B10: Kidera | C10: 724/24 | D10: Muwanguzi Timothy | E10: 17 | F10: 1 | G10: M | H10: Rhabdomyosarcoma | I10: Ca | M10: 1 | P10: 1 | V10: 1 | AA10: 1 | AC10: 1
A11: 16/12/2024 | B11: Kaliro | C11: 502/24 | D11: Musa Paul | E11: 2.5 | F11: 1 | G11: M | H11: Nephroblastoma | I11: Ca | L11: 1 | P11: 1 | R11: 1 | V11: 1 | Y11: 1 | AC11: 1
A12: 25/8/2023 | B12: Busembatia | C12: 313/23 | D12: Ganyiriba Gorreti | E12: 36 | G12: F | H12: Ca Breast | I12: Ca | K12: 1 | P12: 1 | AC12: 1
A13: 45992 | B13: Kiyunga | C13: 410/23 | D13: Byabona Mirabu | E13: 60 | G13: F | H13: CaCx | I13: Ca | L13: 1 | N13: 1 | T13: 1
A14: 45445 | B14: Kayunga | C14: 041/24 | D14: Nantale Rebecca | E14: 37 | G14: F | H14: Ca Breast | I14: Ca | K14: 1 | P14: 1 | R14: 1 | U14: 1 | V14: 1 | Y14: 1
A15: 20/1/2025 | B15: Bugaya | C15: 753/24 | D15: Namabilo Nayiga Aidha | E15: 50 | G15: F | H15: CaCx | I15: Ca | L15: 1 | N15: 1 | R15: 1 | T15: 1 | V15: 1 | W15: 1
A16: 27/11/2023 | B16: Nawanyago | C16: 0643/23 | D16: Atuhaire Lilian | E16: 35 | G16: F | H16: Ca Breast | I16: Ca | L16: 1 | P16: 1 | V16: 1 | Y16: 1
A17: 45058 | B17: Kagulu | C17: 0525/23 | D17: Lubale Tom | E17: 40 | G17: M | H17: Melanoma | I17: Ca | L17: 1 | P17: 1 | AA17: 1
A18: 45172 | B18: Hospice | C18: 093/23 | D18: Alitra Alexandria | E18: 47 | G18: M | H18: Ca Thyroid | I18: Ca | L18: 1 | P18: 1 | V18: 1 | Y18: 1
A19: 45870 | B19: Lumino | C19: 275/23 | D19: Nerima Margrete | E19: 60 | G19: M | H19: Ca Breast | I19: Ca | L19: 1 | N19: 1 | R19: 1 | V19: 1 | W19: 1
A20: 18/8/2020 | B20: Hospice | C20: 118/20 | D20: Muyanga Florence | E20: 41 | G20: F | H20: Ca Breast | I20: Ca | M20: 1 | P20: 1 | V20: 1 | Y20: 1
A21: 21/11/2022 | B21: Namayingo | C21: 476/21 | D21: Kyakuwaire Teopista | E21: 41 | G21: F | H21: Ca Breast | I21: Ca | M21: 1 | P21: 1 | Y21: 1 | AC21: 1
A22: 22/11/2023 | B22: Muterere | C22: 468/23 | D22: Namirimwe Shaluwa | E22: 27 | G22: F | H22: Ca Breast | I22: Ca | L22: 1 | P22: 1 | Y22: 1 | AA22: 1 | AC22: 1
A23: 17/1/2025 | B23: Nyenga | C23: 496/24 | D23: Akudo Hellen | E23: 34 | G23: F | H23: Ca Breast | I23: Ca | L23: 1 | N23: 1 | T23: 1 | Y23: 1
A24: 19/9/2024 | B24: Kiyindi | C24: 255/24 | D24: Kikomeko Ayub | E24: 67 | G24: M | H24: Ca Oesophagus | I24: Ca | K24: 1 | P24: 1 | R24: 1 | Y24: 1 | AD24: 1
A25: 19/8/2024 | B25: Mbulamuti | C25: 650/24 | D25: Ataliba Shalom | E25: 3 | F25: 1 | G25: F | H25: Retinoblastoma | I25: Ca | L25: 1 | P25: 1 | Y25: 1 | AA25: 1 | AC25: 1
A26: 45870 | B26: Mayuge | C26: 441/24 | D26: Kyewalyanga Betty | E26: 67 | G26: F | H26: Lung Adenocarcinoma | I26: Ca | L26: 1 | N26: 1 | AC26: 1
A27: 20/11/2024 | B27: Buwenge | C27: 462/24 | D27: Achen Riana | E27: 5 | F27: 1 | G27: F | H27: Neuroblastoma | I27: Ca | K27: 1 | P27: 1 | Y27: 1 | AD27: 1 | AF27: 1
A28: 13/6/2024 | B28: Busembatia | C28: 191/24 | D28: Naigembe Juliet | E28: 38 | G28: F | H28: CaCx | I28: Ca | L28: 1 | P28: 1 | Y28: 1
A29: 45177 | B29: Kidera | C29: 324/23 | D29: Mutesi Hellen | E29: 52 | G29: F | H29: Ca Nose | I29: Ca | L29: 1 | P29: 1 | Y29: 1
A30: 16/8/2024 | B30: Budondo | C30: 322/23 | D30: Kintu Aggrey | E30: 64 | G30: M | H30: Ca Prostate | I30: Ca | L30: 1 | P30: 1 | Y30: 1
A31: 45115 | B31: Namayingo | C31: 228/23 | D31: Erumbi Kasifa | E31: 32 | G31: F | H31: Fibrosarcoma | I31: Ca | L31: 1 | P31: 1 | Y31: 1
A32: 25/10/2024 | B32: Budondo | C32: 408/24 | D32: Nabudde Aisha | E32: 26 | G32: F | H32: Ca Breast | I32: Ca | L32: 1 | P32: 1 | Y32: 1
A33: 29/4/2024 | B33: Bugembe | C33: 113/24 | D33: Namugaaju Bernadette | E33: 56 | G33: F | H33: Lymphoma | I33: Ca | M33: 1 | P33: 1 | Y33: 1
A34: 45574 | B34: Budondo | C34: 451/23 | D34: Nankabirwa Rosemary | E34: 50 | G34: F | H34: Ca Rectum | I34: Ca | L34: 1 | P34: 1 | Y34: 1
A35: 45748 | B35: Iganga | C35: 398/24 | D35: Namulinda Florence | E35: 55 | G35: F | H35: Ca Oesophagus | I35: Ca | L35: 1 | N35: 1 | Y35: 1
A36: 13/8/2024 | B36: Buyende | C36: 714/24 | D36: Musana Joseph | E36: 60 | G36: M | H36: Endemic KS | I36: Ca | L36: 1 | P36: 1 | Y36: 1
A37: 21/6/2023 | B37: Buwenge | C37: 260/23 | D37: Takoze John | E37: 57 | G37: M | H37: Ca Prostate | I37: Ca | L37: 1 | P37: 1 | Y37: 1
A38: 23/1/2024 | B38: Kamuli | C38: 613/24 | D38: Mukyala Hellen | E38: 20 | G38: F | H38: Endemic KS | I38: Ca | L38: 1 | P38: 1 | Y38: 1
A39: 29/9/2022 | B39: Kamuli | C39: 0391/21 | D39: Isabirye Sulaiman | E39: 74 | G39: M | H39: Ca Prostate | I39: Ca | L39: 1 | P39: 1 | Y39: 1
A40: 45870 | B40: Namasagali | C40: 746/24 | D40: Nampuli Monica | E40: 31 | G40: F | H40: Ca Breast | I40: Ca | L40: 1 | N40: 1 | Y40: 1
...

Sheet Treatment summary
A1: Route | B1: Total | C1: M | D1: F | E1: Ca | F1: Ca/HIV | G1: HIV | H1: Others | I1: New | J1: Old pts | K1: R/Chem | L1: M/Chem | M1: R/Radio | N1: M/Radio
A2: Banda | B2: =COUNTIF('Treatment Record'!B:B,"Banda") -> 1 | C2: =COUNTIFS('Treatment Record'!B:B,"Banda", 'Treatment Record'!G:G, "M") -> 1 | D2: =COUNTIFS('Treatment Record'!B:B,"Banda", 'Treatment Record'!G:G, "F") -> 0 | E2: =COUNTIFS('Treatment Record'!B:B,"Banda", 'Treatment Record'!I:I, "Ca") -> 1 | F2: =COUNTIFS('Treatment Record'!B:B,"Banda", 'Treatment Record'!I:I, "Ca/HIV") -> 0 | G2: =COUNTIFS('Treatment Record'!B:B,"Banda", 'Treatment Record'!I:I, "HIV") -> 0 | H2: =COUNTIFS('Treatment Record'!B:B,"Banda", 'Treatment Record'!I:I, "Other") -> 0 | I2: =SUMIFS('Treatment Record'!N:N, 'Treatment Record'!B:B, "Banda") -> 0 | J2: =SUMIFS('Treatment Record'!P:P, 'Treatment Record'!B:B, "Banda") -> 1 | K2: =SUMIFS('Treatment Record'!S:S, 'Treatment Record'!B:B, "Banda") -> 0 | L2: 0 | M2: =SUMIFS('Treatment Record'!T:T, 'Treatment Record'!B:B, "Banda") -> 0 | N2: 0
A3: Budiima/Butagaya | B3: =COUNTIF('Treatment Record'!B:B,"Budiima") -> 0 | C3: =COUNTIFS('Treatment Record'!B:B,"Budiima", 'Treatment Record'!G:G, "M") -> 0 | D3: =COUNTIFS('Treatment Record'!B:B,"Budiima", 'Treatment Record'!G:G, "F") -> 0 | E3: =COUNTIFS('Treatment Record'!B:B,"Budiima", 'Treatment Record'!I:I, "Ca") -> 0 | F3: =COUNTIFS('Treatment Record'!B:B,"Budiima", 'Treatment Record'!I:I, "Ca/HIV") -> 0 | G3: =COUNTIFS('Treatment Record'!B:B,"Budiima", 'Treatment Record'!I:I, "HIV") -> 0 | H3: =COUNTIFS('Treatment Record'!B:B,"Budiima", 'Treatment Record'!I:I, "Other") -> 0 | I3: =SUMIFS('Treatment Record'!N:N, 'Treatment Record'!B:B, "Budiima") -> 0 | J3: =SUMIFS('Treatment Record'!P:P, 'Treatment Record'!B:B, "Budiima") -> 0 | K3: =SUMIFS('Treatment Record'!S:S, 'Treatment Record'!B:B, "Budiima") -> 0 | L3: 0 | M3: =SUMIFS('Treatment Record'!T:T, 'Treatment Record'!B:B, "Budiima") -> 0 | N3: 0
A4: Budondo | B4: =COUNTIF('Treatment Record'!B:B,"Budondo") -> 4 | C4: =COUNTIFS('Treatment Record'!B:B,"Budondo", 'Treatment Record'!G:G, "M") -> 1 | D4: =COUNTIFS('Treatment Record'!B:B,"Budondo", 'Treatment Record'!G:G, "F") -> 3 | E4: =COUNTIFS('Treatment Record'!B:B,"Budondo", 'Treatment Record'!I:I, "Ca") -> 4 | F4: =COUNTIFS('Treatment Record'!B:B,"Budondo", 'Treatment Record'!I:I, "Ca/HIV") -> 0 | G4: =COUNTIFS('Treatment Record'!B:B,"Budondo", 'Treatment Record'!I:I, "HIV") -> 0 | H4: =COUNTIFS('Treatment Record'!B:B,"Budondo", 'Treatment Record'!I:I, "Other") -> 0 | I4: =SUMIFS('Treatment Record'!N:N, 'Treatment Record'!B:B, "Budondo") -> 0 | J4: =SUMIFS('Treatment Record'!P:P, 'Treatment Record'!B:B, "Budondo") -> 4 | K4: =SUMIFS('Treatment Record'!S:S, 'Treatment Record'!B:B, "Budondo") -> 0 | L4: 0 | M4: =SUMIFS('Treatment Record'!T:T, 'Treatment Record'!B:B, "Budondo") -> 0 | N4: 0 | Q4: PROFILE %
A5: Bugaya | B5: =COUNTIF('Treatment Record'!B:B,"Bugaya") -> 2 | C5: =COUNTIFS('Treatment Record'!B:B,"Bugaya", 'Treatment Record'!G:G, "M") -> 0 | D5: =COUNTIFS('Treatment Record'!B:B,"Bugaya", 'Treatment Record'!G:G, "F") -> 2 | E5: =COUNTIFS('Treatment Record'!B:B,"Bugaya", 'Treatment Record'!I:I, "Ca") -> 2 | F5: =COUNTIFS('Treatment Record'!B:B,"Bugaya", 'Treatment Record'!I:I, "Ca/HIV") -> 0 | G5: =COUNTIFS('Treatment Record'!B:B,"Bugaya", 'Treatment Record'!I:I, "HIV") -> 0 | H5: =COUNTIFS('Treatment Record'!B:B,"Bugaya", 'Treatment Record'!I:I, "Other") -> 0 | I5: =SUMIFS('Treatment Record'!N:N, 'Treatment Record'!B:B, "Bugaya") -> 2 | J5: =SUMIFS('Treatment Record'!P:P, 'Treatment Record'!B:B, "Bugaya") -> 0 | K5: =SUMIFS('Treatment Record'!S:S, 'Treatment Record'!B:B, "Bugaya") -> 0 | L5: 0 | M5: =SUMIFS('Treatment Record'!T:T, 'Treatment Record'!B:B, "Bugaya") -> 1 | N5: 0
A6: Bugembe | B6: =COUNTIF('Treatment Record'!B:B,"Bugembe") -> 4 | C6: =COUNTIFS('Treatment Record'!B:B,"Bugembe", 'Treatment Record'!G:G, "M") -> 1 | D6: =COUNTIFS('Treatment Record'!B:B,"Bugembe", 'Treatment Record'!G:G, "F") -> 3 | E6: =COUNTIFS('Treatment Record'!B:B,"Bugembe", 'Treatment Record'!I:I, "Ca") -> 2 | F6: =COUNTIFS('Treatment Record'!B:B,"Bugembe", 'Treatment Record'!I:I, "Ca/HIV") -> 1 | G6: =COUNTIFS('Treatment Record'!B:B,"Bugembe", 'Treatment Record'!I:I, "HIV") -> 0 | H6: =COUNTIFS('Treatment Record'!B:B,"Bugembe", 'Treatment Record'!I:I, "Other") -> 1 | I6: =SUMIFS('Treatment Record'!N:N, 'Treatment Record'!B:B, "Bugembe") -> 2 | J6: =SUMIFS('Treatment Record'!P:P, 'Treatment Record'!B:B, "Bugembe") -> 2 | K6: =SUMIFS('Treatment Record'!S:S, 'Treatment Record'!B:B, "Bugembe") -> 0 | L6: 0 | M6: =SUMIFS('Treatment Record'!T:T, 'Treatment Record'!B:B, "Bugembe") -> 0 | N6: 0
A7: Bugerere | B7: =COUNTIF('Treatment Record'!B:B,"Bugerere") -> 1 | C7: =COUNTIFS('Treatment Record'!B:B,"Bugerere", 'Treatment Record'!G:G, "M") -> 0 | D7: =COUNTIFS('Treatment Record'!B:B,"Bugerere", 'Treatment Record'!G:G, "F") -> 1 | E7: =COUNTIFS('Treatment Record'!B:B,"Bugerere", 'Treatment Record'!I:I, "Ca") -> 1 | F7: =COUNTIFS('Treatment Record'!B:B,"Bugerere", 'Treatment Record'!I:I, "Ca/HIV") -> 0 | G7: =COUNTIFS('Treatment Record'!B:B,"Bugerere", 'Treatment Record'!I:I, "HIV") -> 0 | H7: =COUNTIFS('Treatment Record'!B:B,"Bugerere", 'Treatment Record'!I:I, "Other") -> 0 | I7: =SUMIFS('Treatment Record'!N:N, 'Treatment Record'!B:B, "Bugerere") -> 1 | J7: =SUMIFS('Treatment Record'!P:P, 'Treatment Record'!B:B, "Bugerere") -> 0 | K7: =SUMIFS('Treatment Record'!S:S, 'Treatment Record'!B:B, "Bugerere") -> 0 | L7: 0 | M7: =SUMIFS('Treatment Record'!T:T, 'Treatment Record'!B:B, "Bugerere") -> 0 | N7: 0
A8: Bugiri | B8: =COUNTIF('Treatment Record'!B:B,"Bugiri") -> 1 | C8: =COUNTIFS('Treatment Record'!B:B,"Bugiri", 'Treatment Record'!G:G, "M") -> 0 | D8: =COUNTIFS('Treatment Record'!B:B,"Bugiri", 'Treatment Record'!G:G, "F") -> 1 | E8: =COUNTIFS('Treatment Record'!B:B,"Bugiri", 'Treatment Record'!I:I, "Ca") -> 1 | F8: =COUNTIFS('Treatment Record'!B:B,"Bugiri", 'Treatment Record'!I:I, "Ca/HIV") -> 0 | G8: =COUNTIFS('Treatment Record'!B:B,"Bugiri", 'Treatment Record'!I:I, "HIV") -> 0 | H8: =COUNTIFS('Treatment Record'!B:B,"Bugiri", 'Treatment Record'!I:I, "Other") -> 0 | I8: =SUMIFS('Treatment Record'!N:N, 'Treatment Record'!B:B, "Bugiri") -> 1 | J8: =SUMIFS('Treatment Record'!P:P, 'Treatment Record'!B:B, "Bugiri") -> 0 | K8: =SUMIFS('Treatment Record'!S:S, 'Treatment Record'!B:B, "Bugiri") -> 0 | L8: 0 | M8: =SUMIFS('Treatment Record'!T:T, 'Treatment Record'!B:B, "Bugiri") -> 1 | N8: 0 | Q8: Male | R8: =C39/B39 -> 0.31325301
A9: Bugulumbia/Lulyambuzi | B9: =COUNTIF('Treatment Record'!B:B,"Bugulumbia") -> 2 | C9: =COUNTIFS('Treatment Record'!B:B,"Bugulumbia", 'Treatment Record'!G:G, "M") -> 0 | D9: =COUNTIFS('Treatment Record'!B:B,"Bugulumbia", 'Treatment Record'!G:G, "F") -> 2 | E9: =COUNTIFS('Treatment Record'!B:B,"Bugulumbia", 'Treatment Record'!I:I, "Ca") -> 2 | F9: =COUNTIFS('Treatment Record'!B:B,"Bugulumbia", 'Treatment Record'!I:I, "Ca/HIV") -> 0 | G9: =COUNTIFS('Treatment Record'!B:B,"Bugulumbia", 'Treatment Record'!I:I, "HIV") -> 0 | H9: =COUNTIFS('Treatment Record'!B:B,"Bugulumbia", 'Treatment Record'!I:I, "Other") -> 0 | I9: =SUMIFS('Treatment Record'!N:N, 'Treatment Record'!B:B, "Bugulumbia") -> 1 | J9: =SUMIFS('Treatment Record'!P:P, 'Treatment Record'!B:B, "Bugulumbia") -> 1 | K9: =SUMIFS('Treatment Record'!S:S, 'Treatment Record'!B:B, "Bugulumbia") -> 0 | L9: 0 | M9: =SUMIFS('Treatment Record'!T:T, 'Treatment Record'!B:B, "Bugulumbia") -> 1 | N9: 0 | Q9: Female | R9: =D39/B39 -> 0.68674699
A10: Buhema | B10: =COUNTIF('Treatment Record'!B:B,"Buhema") -> 0 | C10: =COUNTIFS('Treatment Record'!B:B,"Buhema", 'Treatment Record'!G:G, "M") -> 0 | D10: =COUNTIFS('Treatment Record'!B:B,"Buhema", 'Treatment Record'!G:G, "F") -> 0 | E10: =COUNTIFS('Treatment Record'!B:B,"Buhema", 'Treatment Record'!I:I, "Ca") -> 0 | F10: =COUNTIFS('Treatment Record'!B:B,"Buhema", 'Treatment Record'!I:I, "Ca/HIV") -> 0 | G10: =COUNTIFS('Treatment Record'!B:B,"Buhema", 'Treatment Record'!I:I, "HIV") -> 0 | H10: =COUNTIFS('Treatment Record'!B:B,"Buhema", 'Treatment Record'!I:I, "Other") -> 0 | I10: =SUMIFS('Treatment Record'!N:N, 'Treatment Record'!B:B, "Buhema") -> 0 | J10: =SUMIFS('Treatment Record'!P:P, 'Treatment Record'!B:B, "Buhema") -> 0 | K10: =SUMIFS('Treatment Record'!S:S, 'Treatment Record'!B:B, "Buhema") -> 0 | L10: 0 | M10: =SUMIFS('Treatment Record'!T:T, 'Treatment Record'!B:B, "Buhema") -> 0 | N10: 0
A11: Bukungu | B11: =COUNTIF('Treatment Record'!B:B,"Bukungu") -> 2 | C11: =COUNTIFS('Treatment Record'!B:B,"Bukungu", 'Treatment Record'!G:G, "M") -> 0 | D11: =COUNTIFS('Treatment Record'!B:B,"Bukungu", 'Treatment Record'!G:G, "F") -> 2 | E11: =COUNTIFS('Treatment Record'!B:B,"Bukungu", 'Treatment Record'!I:I, "Ca") -> 1 | F11: =COUNTIFS('Treatment Record'!B:B,"Bukungu", 'Treatment Record'!I:I, "Ca/HIV") -> 0 | G11: =COUNTIFS('Treatment Record'!B:B,"Bukungu", 'Treatment Record'!I:I, "HIV") -> 0 | H11: =COUNTIFS('Treatment Record'!B:B,"Bukungu", 'Treatment Record'!I:I, "Other") -> 1 | I11: =SUMIFS('Treatment Record'!N:N, 'Treatment Record'!B:B, "Bukungu") -> 1 | J11: =SUMIFS('Treatment Record'!P:P, 'Treatment Record'!B:B, "Bukungu") -> 1 | K11: =SUMIFS('Treatment Record'!S:S, 'Treatment Record'!B:B, "Bukungu") -> 0 | L11: 0 | M11: =SUMIFS('Treatment Record'!T:T, 'Treatment Record'!B:B, "Bukungu") -> 0 | N11: 0
A12: Busedde | B12: =COUNTIF('Treatment Record'!B:B,"Busedde") -> 4 | C12: =COUNTIFS('Treatment Record'!B:B,"Busedde", 'Treatment Record'!G:G, "M") -> 2 | D12: =COUNTIFS('Treatment Record'!B:B,"Busedde", 'Treatment Record'!G:G, "F") -> 2 | E12: =COUNTIFS('Treatment Record'!B:B,"Busedde", 'Treatment Record'!I:I, "Ca") -> 4 | F12: =COUNTIFS('Treatment Record'!B:B,"Busedde", 'Treatment Record'!I:I, "Ca/HIV") -> 0 | G12: =COUNTIFS('Treatment Record'!B:B,"Busedde", 'Treatment Record'!I:I, "HIV") -> 0 | H12: =COUNTIFS('Treatment Record'!B:B,"Busedde", 'Treatment Record'!I:I, "Other") -> 0 | I12: =SUMIFS('Treatment Record'!N:N, 'Treatment Record'!B:B, "Busedde") -> 1 | J12: =SUMIFS('Treatment Record'!P:P, 'Treatment Record'!B:B, "Busedde") -> 3 | K12: =SUMIFS('Treatment Record'!S:S, 'Treatment Record'!B:B, "Busedde") -> 0 | L12: 0 | M12: =SUMIFS('Treatment Record'!T:T, 'Treatment Record'!B:B, "Busedde") -> 0 | N12: 0
A13: Busembatia | B13: =COUNTIF('Treatment Record'!B:B,"Busembatia") -> 7 | C13: =COUNTIFS('Treatment Record'!B:B,"Busembatia", 'Treatment Record'!G:G, "M") -> 0 | D13: =COUNTIFS('Treatment Record'!B:B,"Busembatia", 'Treatment Record'!G:G, "F") -> 7 | E13: =COUNTIFS('Treatment Record'!B:B,"Busembatia", 'Treatment Record'!I:I, "Ca") -> 6 | F13: =COUNTIFS('Treatment Record'!B:B,"Busembatia", 'Treatment Record'!I:I, "Ca/HIV") -> 0 | G13: =COUNTIFS('Treatment Record'!B:B,"Busembatia", 'Treatment Record'!I:I, "HIV") -> 0 | H13: =COUNTIFS('Treatment Record'!B:B,"Busembatia", 'Treatment Record'!I:I, "Other") -> 1 | I13: =SUMIFS('Treatment Record'!N:N, 'Treatment Record'!B:B, "Busembatia") -> 2 | J13: =SUMIFS('Treatment Record'!P:P, 'Treatment Record'!B:B, "Busembatia") -> 5 | K13: =SUMIFS('Treatment Record'!S:S, 'Treatment Record'!B:B, "Busembatia") -> 0 | L13: 0 | M13: =SUMIFS('Treatment Record'!T:T, 'Treatment Record'!B:B, "Busembatia") -> 0 | N13: 0 | Q13: Diagnosis %
A14: Busia | B14: =COUNTIF('Treatment Record'!B:B,"Busia") -> 0 | C14: =COUNTIFS('Treatment Record'!B:B,"Busia", 'Treatment Record'!G:G, "M") -> 0 | D14: =COUNTIFS('Treatment Record'!B:B,"Busia", 'Treatment Record'!G:G, "F") -> 0 | E14: =COUNTIFS('Treatment Record'!B:B,"Busia", 'Treatment Record'!I:I, "Ca") -> 0 | F14: =COUNTIFS('Treatment Record'!B:B,"Busia", 'Treatment Record'!I:I, "Ca/HIV") -> 0 | G14: =COUNTIFS('Treatment Record'!B:B,"Busia", 'Treatment Record'!I:I, "HIV") -> 0 | H14: =COUNTIFS('Treatment Record'!B:B,"Busia", 'Treatment Record'!I:I, "Other") -> 0 | I14: =SUMIFS('Treatment Record'!N:N, 'Treatment Record'!B:B, "Busia") -> 0 | J14: =SUMIFS('Treatment Record'!P:P, 'Treatment Record'!B:B, "Busia") -> 0 | K14: =SUMIFS('Treatment Record'!S:S, 'Treatment Record'!B:B, "Busia") -> 0 | L14: 0 | M14: =SUMIFS('Treatment Record'!T:T, 'Treatment Record'!B:B, "Busia") -> 0 | N14: 0
A15: Buwenge | B15: =COUNTIF('Treatment Record'!B:B,"Buwenge") -> 3 | C15: =COUNTIFS('Treatment Record'!B:B,"Buwenge", 'Treatment Record'!G:G, "M") -> 1 | D15: =COUNTIFS('Treatment Record'!B:B,"Buwenge", 'Treatment Record'!G:G, "F") -> 2 | E15: =COUNTIFS('Treatment Record'!B:B,"Buwenge", 'Treatment Record'!I:I, "Ca") -> 3 | F15: =COUNTIFS('Treatment Record'!B:B,"Buwenge", 'Treatment Record'!I:I, "Ca/HIV") -> 0 | G15: =COUNTIFS('Treatment Record'!B:B,"Buwenge", 'Treatment Record'!I:I, "HIV") -> 0 | H15: =COUNTIFS('Treatment Record'!B:B,"Buwenge", 'Treatment Record'!I:I, "Other") -> 0 | I15: =SUMIFS('Treatment Record'!N:N, 'Treatment Record'!B:B, "Buwenge") -> 0 | J15: =SUMIFS('Treatment Record'!P:P, 'Treatment Record'!B:B, "Buwenge") -> 3 | K15: =SUMIFS('Treatment Record'!S:S, 'Treatment Record'!B:B, "Buwenge") -> 0 | L15: 0 | M15: =SUMIFS('Treatment Record'!T:T, 'Treatment Record'!B:B, "Buwenge") -> 0 | N15: 0 | Q15: Ca | R15: =E39/B39 -> 0.86746988
A16: Buyende | B16: =COUNTIF('Treatment Record'!B:B,"Buyende") -> 5 | C16: =COUNTIFS('Treatment Record'!B:B,"Buyende", 'Treatment Record'!G:G, "M") -> 4 | D16: =COUNTIFS('Treatment Record'!B:B,"Buyende", 'Treatment Record'!G:G, "F") -> 1 | E16: =COUNTIFS('Treatment Record'!B:B,"Buyende", 'Treatment Record'!I:I, "Ca") -> 4 | F16: =COUNTIFS('Treatment Record'!B:B,"Buyende", 'Treatment Record'!I:I, "Ca/HIV") -> 0 | G16: =COUNTIFS('Treatment Record'!B:B,"Buyende", 'Treatment Record'!I:I, "HIV") -> 0 | H16: =COUNTIFS('Treatment Record'!B:B,"Buyende", 'Treatment Record'!I:I, "Other") -> 1 | I16: =SUMIFS('Treatment Record'!N:N, 'Treatment Record'!B:B, "Buyende") -> 2 | J16: =SUMIFS('Treatment Record'!P:P, 'Treatment Record'!B:B, "Buyende") -> 3 | K16: =SUMIFS('Treatment Record'!S:S, 'Treatment Record'!B:B, "Buyende") -> 0 | L16: 0 | M16: =SUMIFS('Treatment Record'!T:T, 'Treatment Record'!B:B, "Buyende") -> 0 | N16: 0 | Q16: Ca/HIV | R16: =F39/B39 -> 0.084337349
A17: Hospice Jinja | B17: =COUNTIF('Treatment Record'!B:B,"Hospice") -> 2 | C17: =COUNTIFS('Treatment Record'!B:B,"Hospice", 'Treatment Record'!G:G, "M") -> 1 | D17: =COUNTIFS('Treatment Record'!B:B,"Hospice", 'Treatment Record'!G:G, "F") -> 1 | E17: =COUNTIFS('Treatment Record'!B:B,"Hospice", 'Treatment Record'!I:I, "Ca") -> 2 | F17: =COUNTIFS('Treatment Record'!B:B,"Hospice", 'Treatment Record'!I:I, "Ca/HIV") -> 0 | G17: =COUNTIFS('Treatment Record'!B:B,"Hospice", 'Treatment Record'!I:I, "HIV") -> 0 | H17: =COUNTIFS('Treatment Record'!B:B,"Hospice", 'Treatment Record'!I:I, "Other") -> 0 | I17: =SUMIFS('Treatment Record'!N:N, 'Treatment Record'!B:B, "Hospice") -> 0 | J17: =SUMIFS('Treatment Record'!P:P, 'Treatment Record'!B:B, "Hospice") -> 2 | K17: =SUMIFS('Treatment Record'!S:S, 'Treatment Record'!B:B, "Hospice") -> 0 | L17: 0 | M17: =SUMIFS('Treatment Record'!T:T, 'Treatment Record'!B:B, "Hospice") -> 0 | N17: 0 | Q17: HIV | R17: =G39/B39 -> 0
A18: Iganga Ibulanka | B18: =COUNTIF('Treatment Record'!B:B,"Iganga") -> 4 | C18: =COUNTIFS('Treatment Record'!B:B,"Iganga", 'Treatment Record'!G:G, "M") -> 2 | D18: =COUNTIFS('Treatment Record'!B:B,"Iganga", 'Treatment Record'!G:G, "F") -> 2 | E18: =COUNTIFS('Treatment Record'!B:B,"Iganga", 'Treatment Record'!I:I, "Ca") -> 3 | F18: =COUNTIFS('Treatment Record'!B:B,"Iganga", 'Treatment Record'!I:I, "Ca/HIV") -> 1 | G18: =COUNTIFS('Treatment Record'!B:B,"Iganga", 'Treatment Record'!I:I, "HIV") -> 0 | H18: =COUNTIFS('Treatment Record'!B:B,"Iganga", 'Treatment Record'!I:I, "Other") -> 0 | I18: =SUMIFS('Treatment Record'!N:N, 'Treatment Record'!B:B, "Iganga") -> 2 | J18: =SUMIFS('Treatment Record'!P:P, 'Treatment Record'!B:B, "Iganga") -> 2 | K18: =SUMIFS('Treatment Record'!S:S, 'Treatment Record'!B:B, "Iganga") -> 0 | L18: 0 | M18: =SUMIFS('Treatment Record'!T:T, 'Treatment Record'!B:B, "Iganga") -> 0 | N18: 0 | Q18: Others | R18: =H39/B39 -> 0.048192771
A19: Ivukula | B19: =COUNTIF('Treatment Record'!B:B,"Ivukula") -> 3 | C19: =COUNTIFS('Treatment Record'!B:B,"Ivukula", 'Treatment Record'!G:G, "M") -> 2 | D19: =COUNTIFS('Treatment Record'!B:B,"Ivukula", 'Treatment Record'!G:G, "F") -> 1 | E19: =COUNTIFS('Treatment Record'!B:B,"Ivukula", 'Treatment Record'!I:I, "Ca") -> 2 | F19: =COUNTIFS('Treatment Record'!B:B,"Ivukula", 'Treatment Record'!I:I, "Ca/HIV") -> 1 | G19: =COUNTIFS('Treatment Record'!B:B,"Ivukula", 'Treatment Record'!I:I, "HIV") -> 0 | H19: =COUNTIFS('Treatment Record'!B:B,"Ivukula", 'Treatment Record'!I:I, "Other") -> 0 | I19: =SUMIFS('Treatment Record'!N:N, 'Treatment Record'!B:B, "Ivukula") -> 1 | J19: =SUMIFS('Treatment Record'!P:P, 'Treatment Record'!B:B, "Ivukula") -> 2 | K19: =SUMIFS('Treatment Record'!S:S, 'Treatment Record'!B:B, "Ivukula") -> 0 | L19: 0 | M19: =SUMIFS('Treatment Record'!T:T, 'Treatment Record'!B:B, "Ivukula") -> 0 | N19: 0
A20: Kagulu | B20: =COUNTIF('Treatment Record'!B:B,"Kagulu") -> 2 | C20: =COUNTIFS('Treatment Record'!B:B,"Kagulu", 'Treatment Record'!G:G, "M") -> 1 | D20: =COUNTIFS('Treatment Record'!B:B,"Kagulu", 'Treatment Record'!G:G, "F") -> 1 | E20: =COUNTIFS('Treatment Record'!B:B,"Kagulu", 'Treatment Record'!I:I, "Ca") -> 2 | F20: =COUNTIFS('Treatment Record'!B:B,"Kagulu", 'Treatment Record'!I:I, "Ca/HIV") -> 0 | G20: =COUNTIFS('Treatment Record'!B:B,"Kagulu", 'Treatment Record'!I:I, "HIV") -> 0 | H20: =COUNTIFS('Treatment Record'!B:B,"Kagulu", 'Treatment Record'!I:I, "Other") -> 0 | I20: =SUMIFS('Treatment Record'!N:N, 'Treatment Record'!B:B, "Kagulu") -> 0 | J20: =SUMIFS('Treatment Record'!P:P, 'Treatment Record'!B:B, "Kagulu") -> 2 | K20: =SUMIFS('Treatment Record'!S:S, 'Treatment Record'!B:B, "Kagulu") -> 0 | L20: 0 | M20: =SUMIFS('Treatment Record'!T:T, 'Treatment Record'!B:B, "Kagulu") -> 0 | N20: 0
A21: Kagumba | B21: =COUNTIF('Treatment Record'!B:B,"Kagumba") -> 0 | C21: =COUNTIFS('Treatment Record'!B:B,"Kagumba", 'Treatment Record'!G:G, "M") -> 0 | D21: =COUNTIFS('Treatment Record'!B:B,"Kagumba", 'Treatment Record'!G:G, "F") -> 0 | E21: =COUNTIFS('Treatment Record'!B:B,"Kagumba", 'Treatment Record'!I:I, "Ca") -> 0 | F21: =COUNTIFS('Treatment Record'!B:B,"Kagumba", 'Treatment Record'!I:I, "Ca/HIV") -> 0 | G21: =COUNTIFS('Treatment Record'!B:B,"Kagumba", 'Treatment Record'!I:I, "HIV") -> 0 | H21: =COUNTIFS('Treatment Record'!B:B,"Kagumba", 'Treatment Record'!I:I, "Other") -> 0 | I21: =SUMIFS('Treatment Record'!N:N, 'Treatment Record'!B:B, "Kagumba") -> 0 | J21: =SUMIFS('Treatment Record'!P:P, 'Treatment Record'!B:B, "Kagumba") -> 0 | K21: =SUMIFS('Treatment Record'!S:S, 'Treatment Record'!B:B, "Kagumba") -> 0 | L21: 0 | M21: =SUMIFS('Treatment Record'!T:T, 'Treatment Record'!B:B, "Kagumba") -> 0 | N21: 0
A22: Kaliro | B22: =COUNTIF('Treatment Record'!B:B,"Kaliro") -> 3 | C22: =COUNTIFS('Treatment Record'!B:B,"Kaliro", 'Treatment Record'!G:G, "M") -> 1 | D22: =COUNTIFS('Treatment Record'!B:B,"Kaliro", 'Treatment Record'!G:G, "F") -> 2 | E22: =COUNTIFS('Treatment Record'!B:B,"Kaliro", 'Treatment Record'!I:I, "Ca") -> 3 | F22: =COUNTIFS('Treatment Record'!B:B,"Kaliro", 'Treatment Record'!I:I, "Ca/HIV") -> 0 | G22: =COUNTIFS('Treatment Record'!B:B,"Kaliro", 'Treatment Record'!I:I, "HIV") -> 0 | H22: =COUNTIFS('Treatment Record'!B:B,"Kaliro", 'Treatment Record'!I:I, "Other") -> 0 | I22: =SUMIFS('Treatment Record'!N:N, 'Treatment Record'!B:B, "Kaliro") -> 1 | J22: =SUMIFS('Treatment Record'!P:P, 'Treatment Record'!B:B, "Kaliro") -> 2 | K22: =SUMIFS('Treatment Record'!S:S, 'Treatment Record'!B:B, "Kaliro") -> 0 | L22: 0 | M22: =SUMIFS('Treatment Record'!T:T, 'Treatment Record'!B:B, "Kaliro") -> 0 | N22: 0
A23: Kamuli | B23: =COUNTIF('Treatment Record'!B:B,"Kamuli") -> 2 | C23: =COUNTIFS('Treatment Record'!B:B,"Kamuli", 'Treatment Record'!G:G, "M") -> 1 | D23: =COUNTIFS('Treatment Record'!B:B,"Kamuli", 'Treatment Record'!G:G, "F") -> 1 | E23: =COUNTIFS('Treatment Record'!B:B,"Kamuli", 'Treatment Record'!I:I, "Ca") -> 2 | F23: =COUNTIFS('Treatment Record'!B:B,"Kamuli", 'Treatment Record'!I:I, "Ca/HIV") -> 0 | G23: =COUNTIFS('Treatment Record'!B:B,"Kamuli", 'Treatment Record'!I:I, "HIV") -> 0 | H23: =COUNTIFS('Treatment Record'!B:B,"Kamuli", 'Treatment Record'!I:I, "Other") -> 0 | I23: =SUMIFS('Treatment Record'!N:N, 'Treatment Record'!B:B, "Kamuli") -> 0 | J23: =SUMIFS('Treatment Record'!P:P, 'Treatment Record'!B:B, "Kamuli") -> 2 | K23: =SUMIFS('Treatment Record'!S:S, 'Treatment Record'!B:B, "Kamuli") -> 0 | L23: 0 | M23: =SUMIFS('Treatment Record'!T:T, 'Treatment Record'!B:B, "Kamuli") -> 0 | N23: 0
A24: Kayunga | B24: =COUNTIF('Treatment Record'!B:B,"Kayunga") -> 5 | C24: =COUNTIFS('Treatment Record'!B:B,"Kayunga", 'Treatment Record'!G:G, "M") -> 1 | D24: =COUNTIFS('Treatment Record'!B:B,"Kayunga", 'Treatment Record'!G:G, "F") -> 4 | E24: =COUNTIFS('Treatment Record'!B:B,"Kayunga", 'Treatment Record'!I:I, "Ca") -> 5 | F24: =COUNTIFS('Treatment Record'!B:B,"Kayunga", 'Treatment Record'!I:I, "Ca/HIV") -> 0 | G24: =COUNTIFS('Treatment Record'!B:B,"Kayunga", 'Treatment Record'!I:I, "HIV") -> 0 | H24: =COUNTIFS('Treatment Record'!B:B,"Kayunga", 'Treatment Record'!I:I, "Other") -> 0 | I24: =SUMIFS('Treatment Record'!N:N, 'Treatment Record'!B:B, "Kayunga") -> 1 | J24: =SUMIFS('Treatment Record'!P:P, 'Treatment Record'!B:B, "Kayunga") -> 4 | K24: =SUMIFS('Treatment Record'!S:S, 'Treatment Record'!B:B, "Kayunga") -> 0 | L24: 0 | M24: =SUMIFS('Treatment Record'!T:T, 'Treatment Record'!B:B, "Kayunga") -> 0 | N24: 0
A25: Kidera | B25: =COUNTIF('Treatment Record'!B:B,"Kidera") -> 2 | C25: =COUNTIFS('Treatment Record'!B:B,"Kidera", 'Treatment Record'!G:G, "M") -> 1 | D25: =COUNTIFS('Treatment Record'!B:B,"Kidera", 'Treatment Record'!G:G, "F") -> 1 | E25: =COUNTIFS('Treatment Record'!B:B,"Kidera", 'Treatment Record'!I:I, "Ca") -> 2 | F25: =COUNTIFS('Treatment Record'!B:B,"Kidera", 'Treatment Record'!I:I, "Ca/HIV") -> 0 | G25: =COUNTIFS('Treatment Record'!B:B,"Kidera", 'Treatment Record'!I:I, "HIV") -> 0 | H25: =COUNTIFS('Treatment Record'!B:B,"Kidera", 'Treatment Record'!I:I, "Other") -> 0 | I25: =SUMIFS('Treatment Record'!N:N, 'Treatment Record'!B:B, "Kidera") -> 0 | J25: =SUMIFS('Treatment Record'!P:P, 'Treatment Record'!B:B, "Kidera") -> 2 | K25: =SUMIFS('Treatment Record'!S:S, 'Treatment Record'!B:B, "Kidera") -> 0 | L25: 0 | M25: =SUMIFS('Treatment Record'!T:T, 'Treatment Record'!B:B, "Kidera") -> 0 | N25: 0
A26: Kiyindi | B26: =COUNTIF('Treatment Record'!B:B,"Kiyindi") -> 2 | C26: =COUNTIFS('Treatment Record'!B:B,"Kiyindi", 'Treatment Record'!G:G, "M") -> 1 | D26: =COUNTIFS('Treatment Record'!B:B,"Kiyindi", 'Treatment Record'!G:G, "F") -> 1 | E26: =COUNTIFS('Treatment Record'!B:B,"Kiyindi", 'Treatment Record'!I:I, "Ca") -> 1 | F26: =COUNTIFS('Treatment Record'!B:B,"Kiyindi", 'Treatment Record'!I:I, "Ca/HIV") -> 1 | G26: =COUNTIFS('Treatment Record'!B:B,"Kiyindi", 'Treatment Record'!I:I, "HIV") -> 0 | H26: =COUNTIFS('Treatment Record'!B:B,"Kiyindi", 'Treatment Record'!I:I, "Other") -> 0 | I26: =SUMIFS('Treatment Record'!N:N, 'Treatment Record'!B:B, "Kiyindi") -> 0 | J26: =SUMIFS('Treatment Record'!P:P, 'Treatment Record'!B:B, "Kiyindi") -> 2 | K26: =SUMIFS('Treatment Record'!S:S, 'Treatment Record'!B:B, "Kiyindi") -> 0 | L26: 0 | M26: =SUMIFS('Treatment Record'!T:T, 'Treatment Record'!B:B, "Kiyindi") -> 0 | N26: 0
A27: Kiyunga | B27: =COUNTIF('Treatment Record'!B:B,"Kiyunga") -> 4 | C27: =COUNTIFS('Treatment Record'!B:B,"Kiyunga", 'Treatment Record'!G:G, "M") -> 0 | D27: =COUNTIFS('Treatment Record'!B:B,"Kiyunga", 'Treatment Record'!G:G, "F") -> 4 | E27: =COUNTIFS('Treatment Record'!B:B,"Kiyunga", 'Treatment Record'!I:I, "Ca") -> 2 | F27: =COUNTIFS('Treatment Record'!B:B,"Kiyunga", 'Treatment Record'!I:I, "Ca/HIV") -> 2 | G27: =COUNTIFS('Treatment Record'!B:B,"Kiyunga", 'Treatment Record'!I:I, "HIV") -> 0 | H27: =COUNTIFS('Treatment Record'!B:B,"Kiyunga", 'Treatment Record'!I:I, "Other") -> 0 | I27: =SUMIFS('Treatment Record'!N:N, 'Treatment Record'!B:B, "Kiyunga") -> 1 | J27: =SUMIFS('Treatment Record'!P:P, 'Treatment Record'!B:B, "Kiyunga") -> 3 | K27: =SUMIFS('Treatment Record'!S:S, 'Treatment Record'!B:B, "Kiyunga") -> 0 | L27: 0 | M27: =SUMIFS('Treatment Record'!T:T, 'Treatment Record'!B:B, "Kiyunga") -> 1 | N27: 0
A28: Lumino | B28: =COUNTIF('Treatment Record'!B:B,"Lumino") -> 1 | C28: =COUNTIFS('Treatment Record'!B:B,"Lumino", 'Treatment Record'!G:G, "M") -> 1 | D28: =COUNTIFS('Treatment Record'!B:B,"Lumino", 'Treatment Record'!G:G, "F") -> 0 | E28: =COUNTIFS('Treatment Record'!B:B,"Lumino", 'Treatment Record'!I:I, "Ca") -> 1 | F28: =COUNTIFS('Treatment Record'!B:B,"Lumino", 'Treatment Record'!I:I, "Ca/HIV") -> 0 | G28: =COUNTIFS('Treatment Record'!B:B,"Lumino", 'Treatment Record'!I:I, "HIV") -> 0 | H28: =COUNTIFS('Treatment Record'!B:B,"Lumino", 'Treatment Record'!I:I, "Other") -> 0 | I28: =SUMIFS('Treatment Record'!N:N, 'Treatment Record'!B:B, "Lumino") -> 1 | J28: =SUMIFS('Treatment Record'!P:P, 'Treatment Record'!B:B, "Lumino") -> 0 | K28: =SUMIFS('Treatment Record'!S:S, 'Treatment Record'!B:B, "Lumino") -> 0 | L28: 0 | M28: =SUMIFS('Treatment Record'!T:T, 'Treatment Record'!B:B, "Lumino") -> 0 | N28: 0
A29: Makuutu | B29: =COUNTIF('Treatment Record'!B:B,"Makuutu") -> 0 | C29: =COUNTIFS('Treatment Record'!B:B,"Makuutu", 'Treatment Record'!G:G, "M") -> 0 | D29: =COUNTIFS('Treatment Record'!B:B,"Makuutu", 'Treatment Record'!G:G, "F") -> 0 | E29: =COUNTIFS('Treatment Record'!B:B,"Makuutu", 'Treatment Record'!I:I, "Ca") -> 0 | F29: =COUNTIFS('Treatment Record'!B:B,"Makuutu", 'Treatment Record'!I:I, "Ca/HIV") -> 0 | G29: =COUNTIFS('Treatment Record'!B:B,"Makuutu", 'Treatment Record'!I:I, "HIV") -> 0 | H29: =COUNTIFS('Treatment Record'!B:B,"Makuutu", 'Treatment Record'!I:I, "Other") -> 0 | I29: =SUMIFS('Treatment Record'!N:N, 'Treatment Record'!B:B, "Makuutu") -> 0 | J29: =SUMIFS('Treatment Record'!P:P, 'Treatment Record'!B:B, "Makuutu") -> 0 | K29: =SUMIFS('Treatment Record'!S:S, 'Treatment Record'!B:B, "Makuutu") -> 0 | L29: 0 | M29: =SUMIFS('Treatment Record'!T:T, 'Treatment Record'!B:B, "Makuutu") -> 0 | N29: 0
A30: Mayuge | B30: =COUNTIF('Treatment Record'!B:B,"Mayuge") -> 1 | C30: =COUNTIFS('Treatment Record'!B:B,"Mayuge", 'Treatment Record'!G:G, "M") -> 0 | D30: =COUNTIFS('Treatment Record'!B:B,"Mayuge", 'Treatment Record'!G:G, "F") -> 1 | E30: =COUNTIFS('Treatment Record'!B:B,"Mayuge", 'Treatment Record'!I:I, "Ca") -> 1 | F30: =COUNTIFS('Treatment Record'!B:B,"Mayuge", 'Treatment Record'!I:I, "Ca/HIV") -> 0 | G30: =COUNTIFS('Treatment Record'!B:B,"Mayuge", 'Treatment Record'!I:I, "HIV") -> 0 | H30: =COUNTIFS('Treatment Record'!B:B,"Mayuge", 'Treatment Record'!I:I, "Other") -> 0 | I30: =SUMIFS('Treatment Record'!N:N, 'Treatment Record'!B:B, "Mayuge") -> 1 | J30: =SUMIFS('Treatment Record'!P:P, 'Treatment Record'!B:B, "Mayuge") -> 0 | K30: =SUMIFS('Treatment Record'!S:S, 'Treatment Record'!B:B, "Mayuge") -> 0 | L30: 0 | M30: =SUMIFS('Treatment Record'!T:T, 'Treatment Record'!B:B, "Mayuge") -> 0 | N30: 0
A31: Mbulamuti | B31: =COUNTIF('Treatment Record'!B:B,"Mbulamuti") -> 1 | C31: =COUNTIFS('Treatment Record'!B:B,"Mbulamuti", 'Treatment Record'!G:G, "M") -> 0 | D31: =COUNTIFS('Treatment Record'!B:B,"Mbulamuti", 'Treatment Record'!G:G, "F") -> 1 | E31: =COUNTIFS('Treatment Record'!B:B,"Mbulamuti", 'Treatment Record'!I:I, "Ca") -> 1 | F31: =COUNTIFS('Treatment Record'!B:B,"Mbulamuti", 'Treatment Record'!I:I, "Ca/HIV") -> 0 | G31: =COUNTIFS('Treatment Record'!B:B,"Mubulamuti", 'Treatment Record'!I:I, "HIV") -> 0 | H31: =COUNTIFS('Treatment Record'!B:B,"Mbulamuti", 'Treatment Record'!I:I, "Other") -> 0 | I31: =SUMIFS('Treatment Record'!N:N, 'Treatment Record'!B:B, "Mbulamuti") -> 0 | J31: =SUMIFS('Treatment Record'!P:P, 'Treatment Record'!B:B, "Mbulamuti") -> 1 | K31: =SUMIFS('Treatment Record'!S:S, 'Treatment Record'!B:B, "Mbulamuti") -> 0 | L31: 0 | M31: 0 | N31: 0 | Q31: Diagnosis
A32: Muterere | B32: =COUNTIF('Treatment Record'!B:B,"Muterere") -> 2 | C32: =COUNTIFS('Treatment Record'!B:B,"Mutererei", 'Treatment Record'!G:G, "M") -> 0 | D32: =COUNTIFS('Treatment Record'!B:B,"Muterere", 'Treatment Record'!G:G, "F") -> 2 | E32: =COUNTIFS('Treatment Record'!B:B,"Muterere", 'Treatment Record'!I:I, "Ca") -> 2 | F32: =COUNTIFS('Treatment Record'!B:B,"Muterere", 'Treatment Record'!I:I, "Ca/HIV") -> 0 | G32: =COUNTIFS('Treatment Record'!B:B,"Muterere", 'Treatment Record'!I:I, "HIV") -> 0 | H32: =COUNTIFS('Treatment Record'!B:B,"Muterere", 'Treatment Record'!I:I, "Other") -> 0 | I32: =SUMIFS('Treatment Record'!N:N, 'Treatment Record'!B:B, "Muterere") -> 1 | J32: =SUMIFS('Treatment Record'!P:P, 'Treatment Record'!B:B, "Muterere") -> 1 | K32: =SUMIFS('Treatment Record'!S:S, 'Treatment Record'!B:B, "Muterere") -> 0 | L32: 0 | M32: 0 | N32: 0 | Q32: Ameloblastoma | R32: 1
A33: Namayingo | B33: =COUNTIF('Treatment Record'!B:B,"Namayingo") -> 3 | C33: =COUNTIFS('Treatment Record'!B:B,"Namayingo", 'Treatment Record'!G:G, "M") -> 1 | D33: =COUNTIFS('Treatment Record'!B:B,"Namayingo", 'Treatment Record'!G:G, "F") -> 2 | E33: =COUNTIFS('Treatment Record'!B:B,"Namayingo", 'Treatment Record'!I:I, "Ca") -> 3 | F33: =COUNTIFS('Treatment Record'!B:B,"Namayingo", 'Treatment Record'!I:I, "Ca/HIV") -> 0 | G33: =COUNTIFS('Treatment Record'!B:B,"Namayingo", 'Treatment Record'!I:I, "HIV") -> 0 | H33: =COUNTIFS('Treatment Record'!B:B,"Namayingo", 'Treatment Record'!I:I, "Other") -> 0 | I33: =SUMIFS('Treatment Record'!N:N, 'Treatment Record'!B:B, "Namayingo") -> 1 | J33: =SUMIFS('Treatment Record'!P:P, 'Treatment Record'!B:B, "Namayingo") -> 2 | K33: =SUMIFS('Treatment Record'!S:S, 'Treatment Record'!B:B, "Namayingo") -> 0 | L33: 0 | M33: =SUMIFS('Treatment Record'!T:T, 'Treatment Record'!B:B, "Namayingo") -> 0 | N33: 0 | Q33: Ca Breast | R33: 21
A34: Namasagali | B34: =COUNTIF('Treatment Record'!B:B,"Namasagali") -> 1 | C34: =COUNTIFS('Treatment Record'!B:B,"Namasagali", 'Treatment Record'!G:G, "M") -> 0 | D34: =COUNTIFS('Treatment Record'!B:B,"Namasagali", 'Treatment Record'!G:G, "F") -> 1 | E34: =COUNTIFS('Treatment Record'!B:B,"Namasagali", 'Treatment Record'!I:I, "Ca") -> 1 | F34: =COUNTIFS('Treatment Record'!B:B,"Namasagali", 'Treatment Record'!I:I, "Ca/HIV") -> 0 | G34: =COUNTIFS('Treatment Record'!B:B,"Namasagali", 'Treatment Record'!I:I, "HIV") -> 0 | H34: =COUNTIFS('Treatment Record'!B:B,"Namasagali", 'Treatment Record'!I:I, "Other") -> 0 | I34: =SUMIFS('Treatment Record'!N:N, 'Treatment Record'!B:B, "Namasagali") -> 1 | J34: =SUMIFS('Treatment Record'!P:P, 'Treatment Record'!B:B, "Namasagali") -> 0 | K34: =SUMIFS('Treatment Record'!S:S, 'Treatment Record'!B:B, "Namasagali") -> 0 | L34: 0 | M34: =SUMIFS('Treatment Record'!T:T, 'Treatment Record'!B:B, "Namasagali") -> 0 | N34: 0 | Q34: Ca Colon | R34: 1
A35: Namungalwe | B35: =COUNTIF('Treatment Record'!B:B,"Namungalwe") -> 2 | C35: =COUNTIFS('Treatment Record'!B:B,"Namungalwe", 'Treatment Record'!G:G, "M") -> 2 | D35: =COUNTIFS('Treatment Record'!B:B,"Namungalwe", 'Treatment Record'!G:G, "F") -> 0 | E35: =COUNTIFS('Treatment Record'!B:B,"Namungalwe", 'Treatment Record'!I:I, "Ca") -> 2 | F35: =COUNTIFS('Treatment Record'!B:B,"Namungalwe", 'Treatment Record'!I:I, "Ca/HIV") -> 0 | G35: =COUNTIFS('Treatment Record'!B:B,"Namungalwe", 'Treatment Record'!I:I, "HIV") -> 0 | H35: =COUNTIFS('Treatment Record'!B:B,"Namungalwe", 'Treatment Record'!I:I, "Other") -> 0 | I35: =SUMIFS('Treatment Record'!N:N, 'Treatment Record'!B:B, "Namungalwe") -> 0 | J35: =SUMIFS('Treatment Record'!P:P, 'Treatment Record'!B:B, "Namungalwe") -> 2 | K35: =SUMIFS('Treatment Record'!S:S, 'Treatment Record'!B:B, "Namungalwe") -> 0 | L35: 0 | M35: =SUMIFS('Treatment Record'!T:T, 'Treatment Record'!B:B, "Namungalwe") -> 0 | N35: 0 | Q35: Ca Colorectal | R35: 1
A36: Nawampiti/Buyengo | B36: =COUNTIF('Treatment Record'!B:B,"Nawampiti") -> 0 | C36: =COUNTIFS('Treatment Record'!B:B,"Nawampiti", 'Treatment Record'!G:G, "M") -> 0 | D36: =COUNTIFS('Treatment Record'!B:B,"Nawampiti", 'Treatment Record'!G:G, "F") -> 0 | E36: =COUNTIFS('Treatment Record'!B:B,"Nawampiti", 'Treatment Record'!I:I, "Ca") -> 0 | F36: =COUNTIFS('Treatment Record'!B:B,"Nawampiti", 'Treatment Record'!I:I, "Ca/HIV") -> 0 | G36: =COUNTIFS('Treatment Record'!B:B,"Nawampiti", 'Treatment Record'!I:I, "HIV") -> 0 | H36: =COUNTIFS('Treatment Record'!B:B,"Nawampiti", 'Treatment Record'!I:I, "Other") -> 0 | I36: =SUMIFS('Treatment Record'!N:N, 'Treatment Record'!B:B, "Nawampiti") -> 0 | J36: =SUMIFS('Treatment Record'!P:P, 'Treatment Record'!B:B, "Nawampiti") -> 0 | K36: =SUMIFS('Treatment Record'!S:S, 'Treatment Record'!B:B, "Nawampiti") -> 0 | L36: 0 | M36: =SUMIFS('Treatment Record'!T:T, 'Treatment Record'!B:B, "Nawampiti") -> 0 | N36: 0 | Q36: CaCx | R36: 13
A37: Nawanyago | B37: =COUNTIF('Treatment Record'!B:B,"Nawanyago") -> 5 | C37: =COUNTIFS('Treatment Record'!B:B,"Nawanyago", 'Treatment Record'!G:G, "M") -> 1 | D37: =COUNTIFS('Treatment Record'!B:B,"Nawanyago", 'Treatment Record'!G:G, "F") -> 4 | E37: =COUNTIFS('Treatment Record'!B:B,"Nawanyago", 'Treatment Record'!I:I, "Ca") -> 4 | F37: =COUNTIFS('Treatment Record'!B:B,"Nawanyago", 'Treatment Record'!I:I, "Ca/HIV") -> 1 | G37: =COUNTIFS('Treatment Record'!B:B,"Nawanyago", 'Treatment Record'!I:I, "HIV") -> 0 | H37: =COUNTIFS('Treatment Record'!B:B,"Nawanyago", 'Treatment Record'!I:I, "Other") -> 0 | I37: =SUMIFS('Treatment Record'!N:N, 'Treatment Record'!B:B, "Nawanyago") -> 1 | J37: =SUMIFS('Treatment Record'!P:P, 'Treatment Record'!B:B, "Nawanyago") -> 4 | K37: =SUMIFS('Treatment Record'!S:S, 'Treatment Record'!B:B, "Nawanyago") -> 0 | L37: 0 | M37: =SUMIFS('Treatment Record'!T:T, 'Treatment Record'!B:B, "Nawanyago") -> 1 | N37: 0 | Q37: CaCx+HIV/AIDS | R37: 3
A38: Nyenga | B38: =COUNTIF('Treatment Record'!B:B,"Nyenga") -> 2 | C38: =COUNTIFS('Treatment Record'!B:B,"Nyenga", 'Treatment Record'!G:G, "M") -> 0 | D38: =COUNTIFS('Treatment Record'!B:B,"Nyenga", 'Treatment Record'!G:G, "F") -> 2 | E38: =COUNTIFS('Treatment Record'!B:B,"Nyenga", 'Treatment Record'!I:I, "Ca") -> 2 | F38: =COUNTIFS('Treatment Record'!B:B,"Nyenga", 'Treatment Record'!I:I, "Ca/HIV") -> 0 | G38: =COUNTIFS('Treatment Record'!B:B,"Nyenga", 'Treatment Record'!I:I, "HIV") -> 0 | H38: =COUNTIFS('Treatment Record'!B:B,"Nyenga", 'Treatment Record'!I:I, "Other") -> 0 | I38: =SUMIFS('Treatment Record'!N:N, 'Treatment Record'!B:B, "Nyenga") -> 1 | J38: =SUMIFS('Treatment Record'!P:P, 'Treatment Record'!B:B, "Nyenga") -> 1 | K38: =SUMIFS('Treatment Record'!S:S, 'Treatment Record'!B:B, "Nyenga") -> 0 | L38: 0 | M38: =SUMIFS('Treatment Record'!T:T, 'Treatment Record'!B:B, "Nyenga") -> 1 | N38: 0 | Q38: Ca Mandible | R38: 1
A39: TOTAL | B39: =SUM(B2:B38) -> 83 | C39: =SUM(C2:C38) -> 26 | D39: =SUM(D2:D38) -> 57 | E39: =SUM(E2:E38) -> 72 | F39: =SUM(F2:F38) -> 7 | G39: =SUM(G2:G38) -> 0 | H39: =SUM(H2:H38) -> 4 | I39: =SUM(I2:I38) -> 26 | ... N39: =SUM(N2:N38) -> 0 | Q39: Ca Nose | R39: 3
Q40: Ca Oesophagus | R40: 2
...

Sheet Monthly Summary
A1: Year | B1: Month | C1: Total | D1: M | E1: F | F1: Ca | G1: Ca/HIV | H1: HIV | I1: Others | J1: New | K1: Old appts | L1: Discharg | M1: RIP
A2: 2020 | B2: January | C2: 40 | D2: 14 | E2: 26 | F2: 32 | G2: 6 | H2: 0 | I2: 2 | J2: 15 | K2: 25 | L2: 0 | M2: 0
B3: February | C3: 39 | D3: 17 | E3: 22 | F3: 31 | G3: 4 | H3: 0 | I3: 4 | J3: 14 | K3: 25 | L3: 0 | M3: 0
B4: March | C4: 36 | D4: 15 | E4: 21 | F4: 29 | G4: 3 | H4: 1 | I4: 3 | J4: 5 | K4: 31 | L4: 0 | M4: 5
B6: April | C6: 14 | D6: 7 | E6: 7 | F6: 12 | G6: 1 | H6: 0 | I6: 1 | J6: 0 | K6: 14 | L6: 0 | M6: 1
B7: May | C7: 11 | D7: 5 | E7: 6 | F7: 10 | G7: 0 | H7: 0 | I7: 1 | J7: 1 | K7: 10 | L7: 0 | M7: 0
B8: June | C8: 24 | D8: 10 | E8: 14 | F8: 15 | G8: 3 | H8: 0 | I8: 6 | J8: 10 | K8: 14 | L8: 0 | M8: 0
B10: July | C10: 28 | D10: 12 | E10: 16 | F10: 23 | G10: 2 | H10: 0 | I10: 3 | J10: 0 | K10: 25 | L10: 1 | M10: 1
B11: August | C11: 32 | D11: 9 | E11: 23 | F11: 25 | G11: 3 | H11: 0 | I11: 4 | J11: 13 | K11: 18 | L11: 0 | M11: 0
B12: September | C12: 20 | D12: 8 | E12: 12 | F12: 16 | G12: 3 | H12: 0 | I12: 2 | J12: 6 | K12: 14 | L12: 0 | M12: 3
B14: October | C14: 39 | D14: 14 | E14: 25 | F14: 25 | G14: 6 | H14: 1 | I14: 7 | J14: 14 | K14: 25 | L14: 0 | M14: 2
B15: November | C15: 43 | D15: 17 | E15: 26 | F15: 28 | G15: 6 | H15: 1 | I15: 7 | J15: 14 | K15: 29 | L15: 1 | M15: 3
B16: December | C16: 19 | D16: 5 | E16: 14 | F16: 13 | G16: 3 | H16: 0 | I16: 3 | J16: 2 | K16: 18 | L16: 0 | M16: 2
D17: =SUM(D2:D16) -> 133 | E17: =SUM(E2:E16) -> 212 | J17: =SUM(J2:J16) -> 94
E19: Number of patients supported 2020 | I19: 119
A21: 2021 | B21: January | C21: 22 | D21: 7 | E21: 14 | F21: 15 | G21: 2 | H21: 1 | I21: 1 | J21: 1 | K21: 16 | L21: 0 | M21: 0
B22: February | C22: 37 | D22: 15 | E22: 22 | F22: 28 | G22: 4 | H22: 0 | I22: 5 | J22: 12 | K22: 25 | L22: 0 | M22: 0
B23: March | C23: 43 | D23: 13 | E23: 30 | F23: 29 | G23: 6 | H23: 0 | I23: 8 | J23: 14 | K23: 29 | L23: 0 | M23: 0
B25: April | C25: 43 | D25: 12 | E25: 31 | F25: 25 | G25: 2 | H25: 1 | I25: 15 | J25: 10 | K25: 33 | L25: 0 | M25: 1
B26: May | C26: 42 | D26: 13 | E26: 29 | F26: 32 | G26: 4 | H26: 0 | I26: 5 | J26: 15 | K26: 27 | L26: 0 | M26: 3
B27: June | C27: 45 | D27: 9 | E27: 36 | F27: 37 | G27: 4 | H27: 1 | I27: 3 | J27: 14 | K27: 31 | L27: 0 | M27: 2
B29: July | C29: 44 | D29: 15 | E29: 29 | F29: 36 | G29: 6 | H29: 0 | I29: 2 | J29: 6 | K29: 38 | L29: 0 | M29: 0
B30: August | C30: 37 | D30: 11 | E30: 26 | F30: 30 | G30: 6 | H30: 0 | I30: 1 | J30: 10 | K30: 26 | L30: 1 | M30: 0
B31: September | C31: 63 | D31: 20 | E31: 43 | F31: 48 | G31: 7 | H31: 0 | I31: 8 | J31: 8 | K31: 55 | L31: 2 | M31: 0
B33: October | C33: 55 | D33: 13 | E33: 42 | F33: 45 | G33: 8 | H33: 0 | I33: 2 | J33: 26 | K33: 29 | L33: 0 | M33: 0
B34: November | C34: 84 | D34: 27 | E34: 57 | F34: 69 | G34: 8 | H34: 0 | I34: 7 | J34: 27 | K34: 57 | L34: 0 | M34: 5
B35: December | C35: 47 | D35: 10 | E35: 37 | F35: 37 | G35: 4 | H35: 0 | I35: 6 | J35: 12 | K35: 35 | L35: 0 | M35: 2
J36: =SUM(J21:J35) -> 155
A39: 2022 | B39: January | C39: 30 | D39: 8 | E39: 22 | F39: 21 | G39: 3 | H39: 0 | I39: 4 | J39: 10 | K39: 20 | L39: 0 | M39: 0
B40: February | C40: 58 | D40: 23 | E40: 35 | F40: 45 | G40: 6 | H40: 0 | I40: 7 | J40: 11 | K40: 47 | L40: 1 | M40: 0
B41: March | C41: 78 | D41: 27 | E41: 51 | F41: 59 | G41: 8 | H41: 1 | I41: 10 | J41: 13 | K41: 65 | L41: 1 | M41: 3
B43: April | C43: 48 | D43: 19 | E43: 29 | F43: 40 | G43: 4 | H43: 0 | I43: 4 | J43: 8 | K43: 40 | L43: 0 | M43: 1
B44: May | C44: 60 | D44: 30 | E44: 30 | F44: 48 | G44: 5 | H44: 0 | I44: 7 | J44: 14 | K44: 46 | L44: 0 | M44: 2
B45: June | C45: 66 | D45: 27 | E45: 39 | F45: 46 | G45: 7 | H45: 2 | I45: 11 | J45: 13 | K45: 54 | L45: 0 | M45: 0
B47: July | C47: 68 | D47: 20 | E47: 48 | F47: 47 | G47: 6 | H47: 4 | I47: 11 | J47: 18 | K47: 50 | L47: 0 | M47: 4
B48: August | C48: 68 | D48: 26 | E48: 42 | F48: 50 | G48: 7 | H48: 0 | I48: 11 | J48: 13 | K48: 55 | L48: 0 | M48: 1
B49: September | C49: 68 | D49: 26 | E49: 42 | F49: 48 | G49: 8 | H49: 1 | I49: 11 | J49: 9 | K49: 59 | L49: 0 | M49: 2
B51: October | C51: 49 | D51: 16 | E51: 33 | F51: 30 | G51: 7 | H51: 3 | I51: 9 | J51: 11 | K51: 38 | L51: 0 | M51: 1
B52: November | C52: 66 | D52: 27 | E52: 38 | F52: 41 | G52: 9 | H52: 0 | I52: 15 | J52: 16 | K52: 50 | L52: 0 | M52: 2
B53: December | C53: 38 | D53: 17 | E53: 21 | F53: 27 | G53: 5 | H53: 1 | I53: 5 | J53: 6 | K53: 32 | L53: 1 | M53: 2
...
