Workbook

Sheet Treatment Record
A1: Date of referal | B1: Route | C1: IP.NO | D1: Name | E1: Age | F1: Child | G1: Sex | H1: Detail Diagnosis | I1: Category | J1: Very Weak | K1: Weak | L1: Fair | M1: Stable | N1: New pts | O1: Reviews | P1: Old pts | Q1: Consultation | R1: Diagnositic Investigation | S1: Chemotharpy | T1: Radiotherapy | U1: Biopsy | V1: Scan | W1: X-ray | X1: Surgery | Y1: Medicine | Z1: Other Treatmt | AA1: Up keep | AB1: Histology | AC1: Transport | AD1: RIP | AE1: No. of days on program | AF1: Discharge | AG1: Directions
A2: 27/11/2024 | B2: Iganga | D2: Bukenya Gerald | E2: 34 | G2: M | H2: KS+HIV/AIDS | I2: Ca/HIV | M2: 1 | P2: 1 | AC2: 1
A3: 45081 | B3: Budiima | D3: Nakimera Mary | E3: 43 | G3: F | H3: HIV/AIDS | I3: HIV | M3: 1 | P3: 1 | AC3: 1
A4: 45332 | B4: Kiyindi | D4: Nakajiri Angel | E4: 48 | G4: F | H4: KS+HIV/AIDS | I4: Ca/HIV | M4: 1 | P4: 1 | AC4: 1
A5: 14/10/2024 | B5: Busembatia | D5: Nahyuha Betty | E5: 27 | G5: F | H5: Ca Breast | I5: Ca | M5: 1 | P5: 1 | AA5: 1 | AC5: 1
A6: 45963 | B6: Kaliro | D6: Namulondo Eve | E6: 37 | G6: F | H6: HIV/AIDS | I6: HIV | L6: 1 | P6: 1 | T6: 1
A7: 45449 | B7: Budondo | D7: Namulondo Jane | E7: 55 | G7: F | H7: Ca Breast | I7: Ca | L7: 1 | P7: 1 | X7: 1 | AA7: 1 | AC7: 1
A8: 13/01/2025 | B8: Kayunga | D8: Namudira Alaisa | E8: 26 | G8: F | H8: Malignant Neoplasm | I8: Ca | L8: 1 | P8: 1 | R8: 1
A9: 29/03/2025 | B9: Kayunga | D9: Kiweewa Joseph | E9: 26 | G9: M | H9: Hodgkins Lymphoma | I9: Ca | L9: 1 | P9: 1 | V9: 1 | W9: 1
A10: 25/04/2024 | B10: Kiyindi | D10: Nazziwa Noeline | E10: 29 | G10: F | H10: Ca Breast | I10: Ca | K10: 1 | P10: 1 | T10: 1 | V10: 1 | Y10: 1
A11: 45904 | B11: Namayingo | D11: Nyawere Margret | E11: 50 | G11: F | H11: CaCx | I11: Ca | L11: 1 | P11: 1 | T11: 1 | AB11: 1
A12: 15/05/2025 | B12: Buhemba | D12: Mukisa Elvis | E12: 13 | F12: 1 | G12: M | H12: Non Hodgkins Lymphoma | I12: Ca | L12: 1 | N12: 1 | V12: 1
A13: 45813 | B13: Bugiri | D13: Namukose Zaina | E13: Ad | G13: F | H13: CaCx+HIV/AIDS | I13: Ca | L13: 1 | N13: 1 | T13: 1
A14: 19/08/2024 | B14: Bugembe | D14: Mukunya Henry | E14: 70 | G14: M | H14: Ca Prostate | I14: Ca | L14: 1 | P14: 1 | V14: 1
A15: 29/09/2021 | B15: Hospice | D15: Kairugavu Faisal | E15: 34 | G15: M | H15: Endmic KS | I15: Ca | M15: 1 | P15: 1 | AC15: 1
A16: 24/10/2023 | B16: Kiyunga | D16: Ntono Elizabeth | E16: 41 | G16: F | H16: Ca Breast+HIV/AIDS | I16: Ca/HIV | L16: 1 | P16: 1 | V16: 1
A17: 15/10/2024 | B17: Namungalwe | D17: Edhiruma Fahad | E17: 23 | G17: M | H17: Soft tissue sarcoma | I17: Ca | K17: 1 | P17: 1 | X17: 1
A18: 24/05/2021 | B18: Busedde | D18: Kasada Awali | E18: 57 | G18: M | H18: Endmic KS | I18: Ca | M18: 1 | P18: 1 | AC18: 1
A19: 45544 | B19: Ivukula | D19: Kabire Christine | E19: 55 | G19: F | H19: CaCx | I19: Ca | L19: 1 | P19: 1 | Y19: 1
A20: 26/03/2024 | B20: Walukuba | D20: Kagoya Sauda | E20: 37 | G20: F | H20: CaCx | I20: Ca | L20: 1 | P20: 1 | Y20: 1
A21: 30/04/2024 | B21: Buyende | D21: Tikyange Anasitanzia | E21: 53 | G21: F | H21: CaCx | I21: Ca | L21: 1 | P21: 1 | Y21: 1
A22: 21/03/2023 | B22: Hospice | D22: Alitra Alexander | E22: 49 | G22: M | H22: Ca Thyroid | I22: Ca | L22: 1 | N22: 1 | Y22: 1
A23: 43956 | B23: Kamuli | D23: Musiba Ruth | E23: 65 | G23: F | H23: Ca Breast | I23: Ca | L23: 1 | P23: 1 | Y23: 1
A24: 27/01/2025 | B24: Kaliro | D24: Nairuba Lydia | E24: 37 | G24: F | H24: Ca Breast | I24: Ca | K24: 1 | P24: 1 | Y24: 1 | AD24: 1
A25: 22/01/2025 | B25: Kiyindi | D25: Kigozi Auther | E25: 6 | F25: 1 | G25: M | H25: Rhabdomyosarcoma | I25: Ca | P25: 1 | AD25: 1
A26: 27/11/2023 | B26: Nawanyago | D26: Atuhaire Lillian | E26: 32 | G26: F | H26: Ca Breast | I26: Ca | L26: 1 | P26: 1 | Y26: 1
A27: 45780 | B27: Bugaya | D27: Ewuliana Reagan | E27: 11 | F27: 1 | G27: M | H27: Wilm's Tumor | I27: Ca | L27: 1 | P27: 1 | Y27: 1
A28: 13/11/2024 | B28: Busedde | D28: Kafuko Sophia | E28: 72 | G28: F | H28: CaCx | I28: Ca | L28: 1 | P28: 1 | Y28: 1
A29: 45840 | B29: Namungalwe | D29: Namukose Esereda | E29: 50 | G29: F | H29: Ca Rectum | I29: Ca | L29: 1 | P29: 1 | Y29: 1
A30: 45874 | B30: Bukungu | D30: Kigenyi Gideon | E30: 9 | F30: 1 | G30: M | H30: Low grade Sarcoma | I30: Ca | L30: 1 | N30: 1 | Y30: 1
A31: 45874 | B31: Mbulamuti | D31: Eryevunye James | E31: 56 | G31: M | H31: Ca Prostate | I31: Ca | L31: 1 | N31: 1 | Y31: 1
A32: 45693 | B32: Namayingo | D32: Tibasima Fatuma | E32: Ad | G32: F | H32: Carvicitis | I32: Other | L32: 1 | N32: 1 | R32: 1
A33: 45662 | B33: Namayingo | D33: Bakulimya Esther | E33: Ad | G33: F | H33: CaCx | I33: Ca | L33: 1 | N33: 1
A34: 45721 | B34: Mbulamuti | D34: Nakisuyi Rose | E34: 30 | G34: F | H34: Ca Breast | I34: Ca | L34: 1 | N34: 1 | V34: 1 | W34: 1
A35: 24/02/2025 | B35: Namayingo | D35: Nabukenya Ruth | E35: 30 | G35: F | H35: CaCx | I35: Ca | L35: 1 | P35: 1 | T35: 1 | Y35: 1 | AA35: 1
A36: 29/01/2025 | B36: Ivukula | D36: Guligo Swaibu | E36: 25 | G36: M | H36: Splenomegally | I36: Other | L36: 1 | P36: 1 | Y36: 1 | AC36: 1
A37: 45145 | B37: Namayingo | D37: Nerima Margrethe | E37: 60 | G37: F | H37: Ca Breast | I37: Ca | L37: 1 | P37: 1 | T37: 1 | AC37: 1
A38: 31/01/2025 | B38: Namayingo | D38: Odong John | E38: 68 | G38: M | H38: Ca Prostate | I38: Ca | L38: 1 | P38: 1 | Y38: 1 | AC38: 1
A39: 45058 | B39: Kagulu | D39: Lubale Tom | E39: 34 | G39: M | H39: Nasal Melanoma | I39: Ca | L39: 1 | P39: 1 | V39: 1
A40: 45996 | B40: Busia | D40: Nafula Immaculate | E40: 26 | G40: F | H40: Ca Breast | I40: Ca | L40: 1 | N40: 1 | V40: 2 | AA40: 1
...

Sheet Treatment Data
A1: Date of referal | B1: Route | C1: IP.NO | D1: Name | E1: Age | F1: Child | G1: Sex | H1: Detail Diagnosis | I1: Category | J1: Very Weak | K1: Weak | L1: Fair | M1: Stable | N1: New pts | O1: Reviews | P1: Old pts | Q1: Consultation | R1: Diagnositic Investigation | S1: Chemotharpy | T1: Radiotherapy | U1: Biopsy | V1: Scan | W1: X-ray | X1: Surgery | Y1: Medicine | Z1: Other Treatmt | AA1: Up keep | AB1: Histology | AC1: Transport | AD1: RIP | AE1: No. of days on program | AF1: Discharge | AG1: Directions
A2: 27/11/2024 | B2: Iganga | D2: Bukenya Gerald | E2: 34 | G2: M | H2: KS+HIV/AIDS | I2: Ca/HIV | M2: 1 | P2: 1 | AC2: 1
A3: 45081 | B3: Budiima | D3: Nakimera Mary | E3: 43 | G3: F | H3: HIV/AIDS | I3: HIV | M3: 1 | P3: 1 | AC3: 1
A4: 45332 | B4: Kiyindi | D4: Nakajiri Angel | E4: 48 | G4: F | H4: KS+HIV/AIDS | I4: Ca/HIV | M4: 1 | P4: 1 | AC4: 1
A5: 14/10/2024 | B5: Busembatia | D5: Nahyuha Betty | E5: 27 | G5: F | H5: Ca Breast | I5: Ca | M5: 1 | P5: 1 | AA5: 1 | AC5: 1
A6: 45963 | B6: Kaliro | D6: Namulondo Eve | E6: 37 | G6: F | H6: HIV/AIDS | I6: HIV | L6: 1 | P6: 1 | T6: 1
A7: 45449 | B7: Budondo | D7: Namulondo Jane | E7: 55 | G7: F | H7: Ca Breast | I7: Ca | L7: 1 | P7: 1 | X7: 1 | AA7: 1 | AC7: 1
A8: 13/01/2025 | B8: Kayunga | D8: Namudira Alaisa | E8: 26 | G8: F | H8: Malignant Neoplasm | I8: Ca | L8: 1 | P8: 1 | R8: 1
A9: 29/03/2025 | B9: Kayunga | D9: Kiweewa Joseph | E9: 26 | G9: M | H9: Hodgkins Lymphoma | I9: Ca | L9: 1 | P9: 1 | V9: 1 | W9: 1
A10: 25/04/2024 | B10: Kiyindi | D10: Nazziwa Noeline | E10: 29 | G10: F | H10: Ca Breast | I10: Ca | K10: 1 | P10: 1 | T10: 1 | V10: 1 | Y10: 1
A11: 45904 | B11: Namayingo | D11: Nyawere Margret | E11: 50 | G11: F | H11: CaCx | I11: Ca | L11: 1 | P11: 1 | T11: 1 | AB11: 1
A12: 15/05/2025 | B12: Buhemba | D12: Mukisa Elvis | E12: 13 | F12: 1 | G12: M | H12: Non Hodgkins Lymphoma | I12: Ca | L12: 1 | N12: 1 | V12: 1
A13: 45813 | B13: Bugiri | D13: Namukose Zaina | E13: Ad | G13: F | H13: CaCx+HIV/AIDS | I13: Ca | L13: 1 | N13: 1 | T13: 1
A14: 19/08/2024 | B14: Bugembe | D14: Mukunya Henry | E14: 70 | G14: M | H14: Ca Prostate | I14: Ca | L14: 1 | P14: 1 | V14: 1
A15: 29/09/2021 | B15: Hospice | D15: Kairugavu Faisal | E15: 34 | G15: M | H15: Endmic KS | I15: Ca | M15: 1 | P15: 1 | AC15: 1
A16: 24/10/2023 | B16: Kiyunga | D16: Ntono Elizabeth | E16: 41 | G16: F | H16: Ca Breast+HIV/AIDS | I16: Ca/HIV | L16: 1 | P16: 1 | V16: 1
A17: 15/10/2024 | B17: Namungalwe | D17: Edhiruma Fahad | E17: 23 | G17: M | H17: Soft tissue sarcoma | I17: Ca | K17: 1 | P17: 1 | X17: 1
A18: 24/05/2021 | B18: Busedde | D18: Kasada Awali | E18: 57 | G18: M | H18: Endmic KS | I18: Ca | M18: 1 | P18: 1 | AC18: 1
A19: 45544 | B19: Ivukula | D19: Kabire Christine | E19: 55 | G19: F | H19: CaCx | I19: Ca | L19: 1 | P19: 1 | Y19: 1
A20: 26/03/2024 | B20: Walukuba | D20: Kagoya Sauda | E20: 37 | G20: F | H20: CaCx | I20: Ca | L20: 1 | P20: 1 | Y20: 1
A21: 30/04/2024 | B21: Buyende | D21: Tikyange Anasitanzia | E21: 53 | G21: F | H21: CaCx | I21: Ca | L21: 1 | P21: 1 | Y21: 1
A22: 21/03/2023 | B22: Hospice | D22: Alitra Alexander | E22: 49 | G22: M | H22: Ca Thyroid | I22: Ca | L22: 1 | N22: 1 | Y22: 1
A23: 43956 | B23: Kamuli | D23: Musiba Ruth | E23: 65 | G23: F | H23: Ca Breast | I23: Ca | L23: 1 | P23: 1 | Y23: 1
A24: 27/01/2025 | B24: Kaliro | D24: Nairuba Lydia | E24: 37 | G24: F | H24: Ca Breast | I24: Ca | K24: 1 | P24: 1 | Y24: 1 | AD24: 1
A25: 22/01/2025 | B25: Kiyindi | D25: Kigozi Auther | E25: 6 | F25: 1 | G25: M | H25: Rhabdomyosarcoma | I25: Ca | P25: 1 | AD25: 1
A26: 27/11/2023 | B26: Nawanyago | D26: Atuhaire Lillian | E26: 32 | G26: F | H26: Ca Breast | I26: Ca | L26: 1 | P26: 1 | Y26: 1
A27: 45780 | B27: Bugaya | D27: Ewuliana Reagan | E27: 11 | F27: 1 | G27: M | H27: Wilm's Tumor | I27: Ca | L27: 1 | P27: 1 | Y27: 1
A28: 13/11/2024 | B28: Busedde | D28: Kafuko Sophia | E28: 72 | G28: F | H28: CaCx | I28: Ca | L28: 1 | P28: 1 | Y28: 1
A29: 45840 | B29: Namungalwe | D29: Namukose Esereda | E29: 50 | G29: F | H29: Ca Rectum | I29: Ca | L29: 1 | P29: 1 | Y29: 1
A30: 45874 | B30: Bukungu | D30: Kigenyi Gideon | E30: 9 | F30: 1 | G30: M | H30: Low grade Sarcoma | I30: Ca | L30: 1 | N30: 1 | Y30: 1
A31: 45874 | B31: Mbulamuti | D31: Eryevunye James | E31: 56 | G31: M | H31: Ca Prostate | I31: Ca | L31: 1 | N31: 1 | Y31: 1
A32: 45693 | B32: Namayingo | D32: Tibasima Fatuma | E32: Ad | G32: F | H32: Carvicitis | I32: Other | L32: 1 | N32: 1 | R32: 1
A33: 45662 | B33: Namayingo | D33: Bakulimya Esther | E33: Ad | G33: F | H33: CaCx | I33: Ca | L33: 1 | N33: 1
A34: 45721 | B34: Mbulamuti | D34: Nakisuyi Rose | E34: 30 | G34: F | H34: Ca Breast | I34: Ca | L34: 1 | N34: 1 | V34: 1 | W34: 1
A35: 24/02/2025 | B35: Namayingo | D35: Nabukenya Ruth | E35: 30 | G35: F | H35: CaCx | I35: Ca | L35: 1 | P35: 1 | T35: 1 | Y35: 1 | AA35: 1
A36: 29/01/2025 | B36: Ivukula | D36: Guligo Swaibu | E36: 25 | G36: M | H36: Splenomegally | I36: Other | L36: 1 | P36: 1 | Y36: 1 | AC36: 1
A37: 45145 | B37: Namayingo | D37: Nerima Margrethe | E37: 60 | G37: F | H37: Ca Breast | I37: Ca | L37: 1 | P37: 1 | T37: 1 | AC37: 1
A38: 31/01/2025 | B38: Namayingo | D38: Odong John | E38: 68 | G38: M | H38: Ca Prostate | I38: Ca | L38: 1 | P38: 1 | Y38: 1 | AC38: 1
A39: 45058 | B39: Kagulu | D39: Lubale Tom | E39: 34 | G39: M | H39: Nasal Melanoma | I39: Ca | L39: 1 | P39: 1 | V39: 1
A40: 45996 | B40: Busia | D40: Nafula Immaculate | E40: 26 | G40: F | H40: Ca Breast | I40: Ca | L40: 1 | N40: 1 | V40: 2 | AA40: 1
...

Sheet Treatment summary
A1: Route | B1: Total | C1: M | D1: F | E1: Ca | F1: Ca/HIV | G1: HIV | H1: Others | I1: New | J1: Old pts | K1: R/Chem | L1: M/Chem | M1: R/Radio | N1: M/Radio
A2: Banda | B2: =COUNTIF('Treatment Record'!B:B,"Banda") -> 0 | C2: =COUNTIFS('Treatment Record'!B:B,"Banda", 'Treatment Record'!G:G, "M") -> 0 | D2: =COUNTIFS('Treatment Record'!B:B,"Banda", 'Treatment Record'!G:G, "F") -> 0 | E2: =COUNTIFS('Treatment Record'!B:B,"Banda", 'Treatment Record'!I:I, "Ca") -> 0 | F2: =COUNTIFS('Treatment Record'!B:B,"Banda", 'Treatment Record'!I:I, "Ca/HIV") -> 0 | G2: =COUNTIFS('Treatment Record'!B:B,"Banda", 'Treatment Record'!I:I, "HIV") -> 0 | H2: =COUNTIFS('Treatment Record'!B:B,"Banda", 'Treatment Record'!I:I, "Other") -> 0 | I2: =SUMIFS('Treatment Record'!N:N, 'Treatment Record'!B:B, "Banda") -> 0 | J2: =SUMIFS('Treatment Record'!P:P, 'Treatment Record'!B:B, "Banda") -> 0 | K2: =SUMIFS('Treatment Record'!S:S, 'Treatment Record'!B:B, "Banda") -> 0 | L2: 0 | M2: =SUMIFS('Treatment Record'!T:T, 'Treatment Record'!B:B, "Banda") -> 0 | N2: 0
A3: Budiima/Butagaya | B3: =COUNTIF('Treatment Record'!B:B,"Budiima") -> 1 | C3: =COUNTIFS('Treatment Record'!B:B,"Budiima", 'Treatment Record'!G:G, "M") -> 0 | D3: =COUNTIFS('Treatment Record'!B:B,"Budiima", 'Treatment Record'!G:G, "F") -> 1 | E3: =COUNTIFS('Treatment Record'!B:B,"Budiima", 'Treatment Record'!I:I, "Ca") -> 0 | F3: =COUNTIFS('Treatment Record'!B:B,"Budiima", 'Treatment Record'!I:I, "Ca/HIV") -> 0 | G3: =COUNTIFS('Treatment Record'!B:B,"Budiima", 'Treatment Record'!I:I, "HIV") -> 1 | H3: =COUNTIFS('Treatment Record'!B:B,"Budiima", 'Treatment Record'!I:I, "Other") -> 0 | I3: =SUMIFS('Treatment Record'!N:N, 'Treatment Record'!B:B, "Budiima") -> 0 | J3: =SUMIFS('Treatment Record'!P:P, 'Treatment Record'!B:B, "Budiima") -> 1 | K3: =SUMIFS('Treatment Record'!S:S, 'Treatment Record'!B:B, "Budiima") -> 0 | L3: 0 | M3: =SUMIFS('Treatment Record'!T:T, 'Treatment Record'!B:B, "Budiima") -> 0 | N3: 0
A4: Budondo | B4: =COUNTIF('Treatment Record'!B:B,"Budondo") -> 2 | C4: =COUNTIFS('Treatment Record'!B:B,"Budondo", 'Treatment Record'!G:G, "M") -> 1 | D4: =COUNTIFS('Treatment Record'!B:B,"Budondo", 'Treatment Record'!G:G, "F") -> 1 | E4: =COUNTIFS('Treatment Record'!B:B,"Budondo", 'Treatment Record'!I:I, "Ca") -> 2 | F4: =COUNTIFS('Treatment Record'!B:B,"Budondo", 'Treatment Record'!I:I, "Ca/HIV") -> 0 | G4: =COUNTIFS('Treatment Record'!B:B,"Budondo", 'Treatment Record'!I:I, "HIV") -> 0 | H4: =COUNTIFS('Treatment Record'!B:B,"Budondo", 'Treatment Record'!I:I, "Other") -> 0 | I4: =SUMIFS('Treatment Record'!N:N, 'Treatment Record'!B:B, "Budondo") -> 0 | J4: =SUMIFS('Treatment Record'!P:P, 'Treatment Record'!B:B, "Budondo") -> 2 | K4: =SUMIFS('Treatment Record'!S:S, 'Treatment Record'!B:B, "Budondo") -> 0 | L4: 0 | M4: =SUMIFS('Treatment Record'!T:T, 'Treatment Record'!B:B, "Budondo") -> 0 | N4: 0 | Q4: PROFILE %
A5: Bugaya | B5: =COUNTIF('Treatment Record'!B:B,"Bugaya") -> 3 | C5: =COUNTIFS('Treatment Record'!B:B,"Bugaya", 'Treatment Record'!G:G, "M") -> 1 | D5: =COUNTIFS('Treatment Record'!B:B,"Bugaya", 'Treatment Record'!G:G, "F") -> 2 | E5: =COUNTIFS('Treatment Record'!B:B,"Bugaya", 'Treatment Record'!I:I, "Ca") -> 2 | F5: =COUNTIFS('Treatment Record'!B:B,"Bugaya", 'Treatment Record'!I:I, "Ca/HIV") -> 0 | G5: =COUNTIFS('Treatment Record'!B:B,"Bugaya", 'Treatment Record'!I:I, "HIV") -> 0 | H5: =COUNTIFS('Treatment Record'!B:B,"Bugaya", 'Treatment Record'!I:I, "Other") -> 1 | I5: =SUMIFS('Treatment Record'!N:N, 'Treatment Record'!B:B, "Bugaya") -> 0 | J5: =SUMIFS('Treatment Record'!P:P, 'Treatment Record'!B:B, "Bugaya") -> 3 | K5: =SUMIFS('Treatment Record'!S:S, 'Treatment Record'!B:B, "Bugaya") -> 0 | L5: 0 | M5: =SUMIFS('Treatment Record'!T:T, 'Treatment Record'!B:B, "Bugaya") -> 0 | N5: 0
A6: Bugembe | B6: =COUNTIF('Treatment Record'!B:B,"Bugembe") -> 4 | C6: =COUNTIFS('Treatment Record'!B:B,"Bugembe", 'Treatment Record'!G:G, "M") -> 1 | D6: =COUNTIFS('Treatment Record'!B:B,"Bugembe", 'Treatment Record'!G:G, "F") -> 3 | E6: =COUNTIFS('Treatment Record'!B:B,"Bugembe", 'Treatment Record'!I:I, "Ca") -> 3 | F6: =COUNTIFS('Treatment Record'!B:B,"Bugembe", 'Treatment Record'!I:I, "Ca/HIV") -> 0 | G6: =COUNTIFS('Treatment Record'!B:B,"Bugembe", 'Treatment Record'!I:I, "HIV") -> 0 | H6: =COUNTIFS('Treatment Record'!B:B,"Bugembe", 'Treatment Record'!I:I, "Other") -> 1 | I6: =SUMIFS('Treatment Record'!N:N, 'Treatment Record'!B:B, "Bugembe") -> 1 | J6: =SUMIFS('Treatment Record'!P:P, 'Treatment Record'!B:B, "Bugembe") -> 3 | K6: =SUMIFS('Treatment Record'!S:S, 'Treatment Record'!B:B, "Bugembe") -> 0 | L6: 0 | M6: =SUMIFS('Treatment Record'!T:T, 'Treatment Record'!B:B, "Bugembe") -> 0 | N6: 0
A7: Bugerere | B7: =COUNTIF('Treatment Record'!B:B,"Bugerere") -> 0 | C7: =COUNTIFS('Treatment Record'!B:B,"Bugerere", 'Treatment Record'!G:G, "M") -> 0 | D7: =COUNTIFS('Treatment Record'!B:B,"Bugerere", 'Treatment Record'!G:G, "F") -> 0 | E7: =COUNTIFS('Treatment Record'!B:B,"Bugerere", 'Treatment Record'!I:I, "Ca") -> 0 | F7: =COUNTIFS('Treatment Record'!B:B,"Bugerere", 'Treatment Record'!I:I, "Ca/HIV") -> 0 | G7: =COUNTIFS('Treatment Record'!B:B,"Bugerere", 'Treatment Record'!I:I, "HIV") -> 0 | H7: =COUNTIFS('Treatment Record'!B:B,"Bugerere", 'Treatment Record'!I:I, "Other") -> 0 | I7: =SUMIFS('Treatment Record'!N:N, 'Treatment Record'!B:B, "Bugerere") -> 0 | J7: =SUMIFS('Treatment Record'!P:P, 'Treatment Record'!B:B, "Bugerere") -> 0 | K7: =SUMIFS('Treatment Record'!S:S, 'Treatment Record'!B:B, "Bugerere") -> 0 | L7: 0 | M7: =SUMIFS('Treatment Record'!T:T, 'Treatment Record'!B:B, "Bugerere") -> 0 | N7: 0
A8: Bugiri | B8: =COUNTIF('Treatment Record'!B:B,"Bugiri") -> 1 | C8: =COUNTIFS('Treatment Record'!B:B,"Bugiri", 'Treatment Record'!G:G, "M") -> 0 | D8: =COUNTIFS('Treatment Record'!B:B,"Bugiri", 'Treatment Record'!G:G, "F") -> 1 | E8: =COUNTIFS('Treatment Record'!B:B,"Bugiri", 'Treatment Record'!I:I, "Ca") -> 1 | F8: =COUNTIFS('Treatment Record'!B:B,"Bugiri", 'Treatment Record'!I:I, "Ca/HIV") -> 0 | G8: =COUNTIFS('Treatment Record'!B:B,"Bugiri", 'Treatment Record'!I:I, "HIV") -> 0 | H8: =COUNTIFS('Treatment Record'!B:B,"Bugiri", 'Treatment Record'!I:I, "Other") -> 0 | I8: =SUMIFS('Treatment Record'!N:N, 'Treatment Record'!B:B, "Bugiri") -> 1 | J8: =SUMIFS('Treatment Record'!P:P, 'Treatment Record'!B:B, "Bugiri") -> 0 | K8: =SUMIFS('Treatment Record'!S:S, 'Treatment Record'!B:B, "Bugiri") -> 0 | L8: 0 | M8: =SUMIFS('Treatment Record'!T:T, 'Treatment Record'!B:B, "Bugiri") -> 1 | N8: 0 | Q8: Male | R8: =C42/B42 -> 0.32352941
A9: Bugulumbia/Lulyambuzi | B9: =COUNTIF('Treatment Record'!B:B,"Bugulumbya") -> 0 | C9: =COUNTIFS('Treatment Record'!B:B,"Bugulumbya", 'Treatment Record'!G:G, "M") -> 0 | D9: =COUNTIFS('Treatment Record'!B:B,"Bugulumbya", 'Treatment Record'!G:G, "F") -> 0 | E9: =COUNTIFS('Treatment Record'!B:B,"Bugulumbya", 'Treatment Record'!I:I, "Ca") -> 0 | F9: =COUNTIFS('Treatment Record'!B:B,"Bugulumbya", 'Treatment Record'!I:I, "Ca/HIV") -> 0 | G9: =COUNTIFS('Treatment Record'!B:B,"Bugulumbya", 'Treatment Record'!I:I, "HIV") -> 0 | H9: =COUNTIFS('Treatment Record'!B:B,"Bugulumbya", 'Treatment Record'!I:I, "Other") -> 0 | I9: =SUMIFS('Treatment Record'!N:N, 'Treatment Record'!B:B, "Bugulumbya") -> 0 | J9: =SUMIFS('Treatment Record'!P:P, 'Treatment Record'!B:B, "Bugulumbya") -> 0 | K9: =SUMIFS('Treatment Record'!S:S, 'Treatment Record'!B:B, "Bugulumbya") -> 0 | L9: 0 | M9: =SUMIFS('Treatment Record'!T:T, 'Treatment Record'!B:B, "Bugulumbya") -> 0 | N9: 0 | Q9: Female | R9: =D42/B42 -> 0.67647059
A10: Buhemba | B10: =COUNTIF('Treatment Record'!B:B,"Buhemba") -> 2 | C10: =COUNTIFS('Treatment Record'!B:B,"Buhemba", 'Treatment Record'!G:G, "M") -> 1 | D10: =COUNTIFS('Treatment Record'!B:B,"Buhemba", 'Treatment Record'!G:G, "F") -> 1 | E10: =COUNTIFS('Treatment Record'!B:B,"Buhemba", 'Treatment Record'!I:I, "Ca") -> 2 | F10: =COUNTIFS('Treatment Record'!B:B,"Buhemba", 'Treatment Record'!I:I, "Ca/HIV") -> 0 | G10: =COUNTIFS('Treatment Record'!B:B,"Buhemba", 'Treatment Record'!I:I, "HIV") -> 0 | H10: =COUNTIFS('Treatment Record'!B:B,"Buhemba", 'Treatment Record'!I:I, "Other") -> 0 | I10: =SUMIFS('Treatment Record'!N:N, 'Treatment Record'!B:B, "Buhemba") -> 1 | J10: =SUMIFS('Treatment Record'!P:P, 'Treatment Record'!B:B, "Buhemba") -> 1 | K10: =SUMIFS('Treatment Record'!S:S, 'Treatment Record'!B:B, "Buhemba") -> 0 | L10: 0 | M10: =SUMIFS('Treatment Record'!T:T, 'Treatment Record'!B:B, "Buhemba") -> 0 | N10: 0
A11: Bukungu | B11: =COUNTIF('Treatment Record'!B:B,"Bukungu") -> 1 | C11: =COUNTIFS('Treatment Record'!B:B,"Bukungu", 'Treatment Record'!G:G, "M") -> 1 | D11: =COUNTIFS('Treatment Record'!B:B,"Bukungu", 'Treatment Record'!G:G, "F") -> 0 | E11: =COUNTIFS('Treatment Record'!B:B,"Bukungu", 'Treatment Record'!I:I, "Ca") -> 1 | F11: =COUNTIFS('Treatment Record'!B:B,"Bukungu", 'Treatment Record'!I:I, "Ca/HIV") -> 0 | G11: =COUNTIFS('Treatment Record'!B:B,"Bukungu", 'Treatment Record'!I:I, "HIV") -> 0 | H11: =COUNTIFS('Treatment Record'!B:B,"Bukungu", 'Treatment Record'!I:I, "Other") -> 0 | I11: =SUMIFS('Treatment Record'!N:N, 'Treatment Record'!B:B, "Bukungu") -> 1 | J11: =SUMIFS('Treatment Record'!P:P, 'Treatment Record'!B:B, "Bukungu") -> 0 | K11: =SUMIFS('Treatment Record'!S:S, 'Treatment Record'!B:B, "Bukungu") -> 0 | L11: 0 | M11: =SUMIFS('Treatment Record'!T:T, 'Treatment Record'!B:B, "Bukungu") -> 0 | N11: 0
A12: Busedde | B12: =COUNTIF('Treatment Record'!B:B,"Busedde") -> 3 | C12: =COUNTIFS('Treatment Record'!B:B,"Busedde", 'Treatment Record'!G:G, "M") -> 1 | D12: =COUNTIFS('Treatment Record'!B:B,"Busedde", 'Treatment Record'!G:G, "F") -> 2 | E12: =COUNTIFS('Treatment Record'!B:B,"Busedde", 'Treatment Record'!I:I, "Ca") -> 3 | F12: =COUNTIFS('Treatment Record'!B:B,"Busedde", 'Treatment Record'!I:I, "Ca/HIV") -> 0 | G12: =COUNTIFS('Treatment Record'!B:B,"Busedde", 'Treatment Record'!I:I, "HIV") -> 0 | H12: =COUNTIFS('Treatment Record'!B:B,"Busedde", 'Treatment Record'!I:I, "Other") -> 0 | I12: =SUMIFS('Treatment Record'!N:N, 'Treatment Record'!B:B, "Busedde") -> 0 | J12: =SUMIFS('Treatment Record'!P:P, 'Treatment Record'!B:B, "Busedde") -> 3 | K12: =SUMIFS('Treatment Record'!S:S, 'Treatment Record'!B:B, "Busedde") -> 0 | L12: 0 | M12: =SUMIFS('Treatment Record'!T:T, 'Treatment Record'!B:B, "Busedde") -> 0 | N12: 0
A13: Busembatia | B13: =COUNTIF('Treatment Record'!B:B,"Busembatia") -> 2 | C13: =COUNTIFS('Treatment Record'!B:B,"Busembatia", 'Treatment Record'!G:G, "M") -> 0 | D13: =COUNTIFS('Treatment Record'!B:B,"Busembatia", 'Treatment Record'!G:G, "F") -> 2 | E13: =COUNTIFS('Treatment Record'!B:B,"Busembatia", 'Treatment Record'!I:I, "Ca") -> 1 | F13: =COUNTIFS('Treatment Record'!B:B,"Busembatia", 'Treatment Record'!I:I, "Ca/HIV") -> 0 | G13: =COUNTIFS('Treatment Record'!B:B,"Busembatia", 'Treatment Record'!I:I, "HIV") -> 0 | H13: =COUNTIFS('Treatment Record'!B:B,"Busembatia", 'Treatment Record'!I:I, "Other") -> 1 | I13: =SUMIFS('Treatment Record'!N:N, 'Treatment Record'!B:B, "Busembatia") -> 0 | J13: =SUMIFS('Treatment Record'!P:P, 'Treatment Record'!B:B, "Busembatia") -> 2 | K13: =SUMIFS('Treatment Record'!S:S, 'Treatment Record'!B:B, "Busembatia") -> 0 | L13: 0 | M13: =SUMIFS('Treatment Record'!T:T, 'Treatment Record'!B:B, "Busembatia") -> 0 | N13: 0 | Q13: Diagnosis %
A14: Busia | B14: =COUNTIF('Treatment Record'!B:B,"Busia") -> 1 | C14: =COUNTIFS('Treatment Record'!B:B,"Busia", 'Treatment Record'!G:G, "M") -> 0 | D14: =COUNTIFS('Treatment Record'!B:B,"Busia", 'Treatment Record'!G:G, "F") -> 1 | E14: =COUNTIFS('Treatment Record'!B:B,"Busia", 'Treatment Record'!I:I, "Ca") -> 1 | F14: =COUNTIFS('Treatment Record'!B:B,"Busia", 'Treatment Record'!I:I, "Ca/HIV") -> 0 | G14: =COUNTIFS('Treatment Record'!B:B,"Busia", 'Treatment Record'!I:I, "HIV") -> 0 | H14: =COUNTIFS('Treatment Record'!B:B,"Busia", 'Treatment Record'!I:I, "Other") -> 0 | I14: =SUMIFS('Treatment Record'!N:N, 'Treatment Record'!B:B, "Busia") -> 1 | J14: =SUMIFS('Treatment Record'!P:P, 'Treatment Record'!B:B, "Busia") -> 0 | K14: =SUMIFS('Treatment Record'!S:S, 'Treatment Record'!B:B, "Busia") -> 0 | L14: 0 | M14: =SUMIFS('Treatment Record'!T:T, 'Treatment Record'!B:B, "Busia") -> 0 | N14: 0
A15: Buwenge | B15: =COUNTIF('Treatment Record'!B:B,"Buwenge") -> 2 | C15: =COUNTIFS('Treatment Record'!B:B,"Buwenge", 'Treatment Record'!G:G, "M") -> 0 | D15: =COUNTIFS('Treatment Record'!B:B,"Buwenge", 'Treatment Record'!G:G, "F") -> 2 | E15: =COUNTIFS('Treatment Record'!B:B,"Buwenge", 'Treatment Record'!I:I, "Ca") -> 2 | F15: =COUNTIFS('Treatment Record'!B:B,"Buwenge", 'Treatment Record'!I:I, "Ca/HIV") -> 0 | G15: =COUNTIFS('Treatment Record'!B:B,"Buwenge", 'Treatment Record'!I:I, "HIV") -> 0 | H15: =COUNTIFS('Treatment Record'!B:B,"Buwenge", 'Treatment Record'!I:I, "Other") -> 0 | I15: =SUMIFS('Treatment Record'!N:N, 'Treatment Record'!B:B, "Buwenge") -> 1 | J15: =SUMIFS('Treatment Record'!P:P, 'Treatment Record'!B:B, "Buwenge") -> 1 | K15: =SUMIFS('Treatment Record'!S:S, 'Treatment Record'!B:B, "Buwenge") -> 0 | L15: 0 | M15: =SUMIFS('Treatment Record'!T:T, 'Treatment Record'!B:B, "Buwenge") -> 0 | N15: 0 | Q15: Ca | R15: =E42/B42 -> 0.82352941
A16: Buyende | B16: =COUNTIF('Treatment Record'!B:B,"Buyende") -> 2 | C16: =COUNTIFS('Treatment Record'!B:B,"Buyende", 'Treatment Record'!G:G, "M") -> 0 | D16: =COUNTIFS('Treatment Record'!B:B,"Buyende", 'Treatment Record'!G:G, "F") -> 2 | E16: =COUNTIFS('Treatment Record'!B:B,"Buyende", 'Treatment Record'!I:I, "Ca") -> 2 | F16: =COUNTIFS('Treatment Record'!B:B,"Buyende", 'Treatment Record'!I:I, "Ca/HIV") -> 0 | G16: =COUNTIFS('Treatment Record'!B:B,"Buyende", 'Treatment Record'!I:I, "HIV") -> 0 | H16: =COUNTIFS('Treatment Record'!B:B,"Buyende", 'Treatment Record'!I:I, "Other") -> 0 | I16: =SUMIFS('Treatment Record'!N:N, 'Treatment Record'!B:B, "Buyende") -> 1 | J16: =SUMIFS('Treatment Record'!P:P, 'Treatment Record'!B:B, "Buyende") -> 1 | K16: =SUMIFS('Treatment Record'!S:S, 'Treatment Record'!B:B, "Buyende") -> 0 | L16: 0 | M16: =SUMIFS('Treatment Record'!T:T, 'Treatment Record'!B:B, "Buyende") -> 0 | N16: 0 | Q16: Ca/HIV | R16: =F42/B42 -> 0.044117647
A17: Hospice Jinja | B17: =COUNTIF('Treatment Record'!B:B,"Hospice") -> 2 | C17: =COUNTIFS('Treatment Record'!B:B,"Hospice", 'Treatment Record'!G:G, "M") -> 2 | D17: =COUNTIFS('Treatment Record'!B:B,"Hospice", 'Treatment Record'!G:G, "F") -> 0 | E17: =COUNTIFS('Treatment Record'!B:B,"Hospice", 'Treatment Record'!I:I, "Ca") -> 2 | F17: =COUNTIFS('Treatment Record'!B:B,"Hospice", 'Treatment Record'!I:I, "Ca/HIV") -> 0 | G17: =COUNTIFS('Treatment Record'!B:B,"Hospice", 'Treatment Record'!I:I, "HIV") -> 0 | H17: =COUNTIFS('Treatment Record'!B:B,"Hospice", 'Treatment Record'!I:I, "Other") -> 0 | I17: =SUMIFS('Treatment Record'!N:N, 'Treatment Record'!B:B, "Hospice") -> 1 | J17: =SUMIFS('Treatment Record'!P:P, 'Treatment Record'!B:B, "Hospice") -> 1 | K17: =SUMIFS('Treatment Record'!S:S, 'Treatment Record'!B:B, "Hospice") -> 0 | L17: 0 | M17: =SUMIFS('Treatment Record'!T:T, 'Treatment Record'!B:B, "Hospice") -> 0 | N17: 0 | Q17: HIV | R17: =G42/B42 -> 0.029411765
A18: Hospice NFO | B18: =COUNTIF('Treatment Record'!B:B,"Hospice NFO") -> 0 | C18: =COUNTIFS('Treatment Record'!B:B,"Hospice NFO", 'Treatment Record'!G:G, "M") -> 0 | D18: =COUNTIFS('Treatment Record'!B:B,"Hospice NFO", 'Treatment Record'!G:G, "F") -> 0 | E18: =COUNTIFS('Treatment Record'!B:B,"Hospice NFO", 'Treatment Record'!I:I, "Ca") -> 0 | F18: =COUNTIFS('Treatment Record'!B:B,"Hospice NFO", 'Treatment Record'!I:I, "Ca/HIV") -> 0 | G18: =COUNTIFS('Treatment Record'!B:B,"Hospice NFO", 'Treatment Record'!I:I, "HIV") -> 0 | H18: =COUNTIFS('Treatment Record'!B:B,"Hospice NFO", 'Treatment Record'!I:I, "Other") -> 0 | I18: =SUMIFS('Treatment Record'!N:N, 'Treatment Record'!B:B, "Hospice NFO") -> 0 | J18: =SUMIFS('Treatment Record'!P:P, 'Treatment Record'!B:B, "Hospice NFO") -> 0 | K18: =SUMIFS('Treatment Record'!S:S, 'Treatment Record'!B:B, "Hospice NFO") -> 0 | L18: 0 | M18: =SUMIFS('Treatment Record'!T:T, 'Treatment Record'!B:B, "Hospice NFO") -> 0 | N18: 0
A19: Iganga Ibulanka | B19: =COUNTIF('Treatment Record'!B:B,"Iganga ") -> 1 | C19: =COUNTIFS('Treatment Record'!B:B,"Iganga ", 'Treatment Record'!G:G, "M") -> 1 | D19: =COUNTIFS('Treatment Record'!B:B,"Iganga ", 'Treatment Record'!G:G, "F") -> 0 | E19: =COUNTIFS('Treatment Record'!B:B,"Iganga ", 'Treatment Record'!I:I, "Ca") -> 0 | F19: =COUNTIFS('Treatment Record'!B:B,"Iganga ", 'Treatment Record'!I:I, "Ca/HIV") -> 1 | G19: =COUNTIFS('Treatment Record'!B:B,"Iganga ", 'Treatment Record'!I:I, "HIV") -> 0 | H19: =COUNTIFS('Treatment Record'!B:B,"Iganga ", 'Treatment Record'!I:I, "Other") -> 0 | I19: =SUMIFS('Treatment Record'!N:N, 'Treatment Record'!B:B, "Iganga ") -> 0 | J19: =SUMIFS('Treatment Record'!P:P, 'Treatment Record'!B:B, "Iganga ") -> 1 | K19: =SUMIFS('Treatment Record'!S:S, 'Treatment Record'!B:B, "Iganga ") -> 0 | L19: 0 | M19: =SUMIFS('Treatment Record'!T:T, 'Treatment Record'!B:B, "Iganga ") -> 0 | N19: 0 | Q19: Others | R19: =H42/B42 -> 0.10294118
A20: Ivukula | B20: =COUNTIF('Treatment Record'!B:B,"Ivukula") -> 2 | C20: =COUNTIFS('Treatment Record'!B:B,"Ivukula", 'Treatment Record'!G:G, "M") -> 1 | D20: =COUNTIFS('Treatment Record'!B:B,"Ivukula", 'Treatment Record'!G:G, "F") -> 1 | E20: =COUNTIFS('Treatment Record'!B:B,"Ivukula", 'Treatment Record'!I:I, "Ca") -> 1 | F20: =COUNTIFS('Treatment Record'!B:B,"Ivukula", 'Treatment Record'!I:I, "Ca/HIV") -> 0 | G20: =COUNTIFS('Treatment Record'!B:B,"Ivukula", 'Treatment Record'!I:I, "HIV") -> 0 | H20: =COUNTIFS('Treatment Record'!B:B,"Ivukula", 'Treatment Record'!I:I, "Other") -> 1 | I20: =SUMIFS('Treatment Record'!N:N, 'Treatment Record'!B:B, "Ivukula") -> 0 | J20: =SUMIFS('Treatment Record'!P:P, 'Treatment Record'!B:B, "Ivukula") -> 2 | K20: =SUMIFS('Treatment Record'!S:S, 'Treatment Record'!B:B, "Ivukula") -> 0 | L20: 0 | M20: =SUMIFS('Treatment Record'!T:T, 'Treatment Record'!B:B, "Ivukula") -> 0 | N20: 0
A21: Kagulu | B21: =COUNTIF('Treatment Record'!B:B,"Kagulu") -> 1 | C21: =COUNTIFS('Treatment Record'!B:B,"Kagulu", 'Treatment Record'!G:G, "M") -> 1 | D21: =COUNTIFS('Treatment Record'!B:B,"Kagulu", 'Treatment Record'!G:G, "F") -> 0 | E21: =COUNTIFS('Treatment Record'!B:B,"Kagulu", 'Treatment Record'!I:I, "Ca") -> 1 | F21: =COUNTIFS('Treatment Record'!B:B,"Kagulu", 'Treatment Record'!I:I, "Ca/HIV") -> 0 | G21: =COUNTIFS('Treatment Record'!B:B,"Kagulu", 'Treatment Record'!I:I, "HIV") -> 0 | H21: =COUNTIFS('Treatment Record'!B:B,"Kagulu", 'Treatment Record'!I:I, "Other") -> 0 | I21: =SUMIFS('Treatment Record'!N:N, 'Treatment Record'!B:B, "Kagulu") -> 0 | J21: =SUMIFS('Treatment Record'!P:P, 'Treatment Record'!B:B, "Kagulu") -> 1 | K21: =SUMIFS('Treatment Record'!S:S, 'Treatment Record'!B:B, "Kagulu") -> 0 | L21: 0 | M21: =SUMIFS('Treatment Record'!T:T, 'Treatment Record'!B:B, "Kagulu") -> 0 | N21: 0 | Q21: Children | R21: =COUNT('Treatment Record'!F:F) -> 8
A22: Kagumba | B22: =COUNTIF('Treatment Record'!B:B,"Kagumba") -> 0 | C22: =COUNTIFS('Treatment Record'!B:B,"Kagumba", 'Treatment Record'!G:G, "M") -> 0 | D22: =COUNTIFS('Treatment Record'!B:B,"Kagumba", 'Treatment Record'!G:G, "F") -> 0 | E22: =COUNTIFS('Treatment Record'!B:B,"Kagumba", 'Treatment Record'!I:I, "Ca") -> 0 | F22: =COUNTIFS('Treatment Record'!B:B,"Kagumba", 'Treatment Record'!I:I, "Ca/HIV") -> 0 | G22: =COUNTIFS('Treatment Record'!B:B,"Kagumba", 'Treatment Record'!I:I, "HIV") -> 0 | H22: =COUNTIFS('Treatment Record'!B:B,"Kagumba", 'Treatment Record'!I:I, "Other") -> 0 | I22: =SUMIFS('Treatment Record'!N:N, 'Treatment Record'!B:B, "Kagumba") -> 0 | J22: =SUMIFS('Treatment Record'!P:P, 'Treatment Record'!B:B, "Kagumba") -> 0 | K22: =SUMIFS('Treatment Record'!S:S, 'Treatment Record'!B:B, "Kagumba") -> 0 | L22: 0 | M22: =SUMIFS('Treatment Record'!T:T, 'Treatment Record'!B:B, "Kagumba") -> 0 | N22: 0 | Q22: Boys | R22: 7
A23: Kaliro | B23: =COUNTIF('Treatment Record'!B:B,"Kaliro") -> 4 | C23: =COUNTIFS('Treatment Record'!B:B,"Kaliro", 'Treatment Record'!G:G, "M") -> 1 | D23: =COUNTIFS('Treatment Record'!B:B,"Kaliro", 'Treatment Record'!G:G, "F") -> 3 | E23: =COUNTIFS('Treatment Record'!B:B,"Kaliro", 'Treatment Record'!I:I, "Ca") -> 2 | F23: =COUNTIFS('Treatment Record'!B:B,"Kaliro", 'Treatment Record'!I:I, "Ca/HIV") -> 0 | G23: =COUNTIFS('Treatment Record'!B:B,"Kaliro", 'Treatment Record'!I:I, "HIV") -> 1 | H23: =COUNTIFS('Treatment Record'!B:B,"Kaliro", 'Treatment Record'!I:I, "Other") -> 1 | I23: =SUMIFS('Treatment Record'!N:N, 'Treatment Record'!B:B, "Kaliro") -> 2 | J23: =SUMIFS('Treatment Record'!P:P, 'Treatment Record'!B:B, "Kaliro") -> 2 | K23: =SUMIFS('Treatment Record'!S:S, 'Treatment Record'!B:B, "Kaliro") -> 0 | L23: 0 | M23: =SUMIFS('Treatment Record'!T:T, 'Treatment Record'!B:B, "Kaliro") -> 1 | N23: 0 | Q23: Girls | R23: 1
A24: Kamuli | B24: =COUNTIF('Treatment Record'!B:B,"Kamuli") -> 2 | C24: =COUNTIFS('Treatment Record'!B:B,"Kamuli", 'Treatment Record'!G:G, "M") -> 1 | D24: =COUNTIFS('Treatment Record'!B:B,"Kamuli", 'Treatment Record'!G:G, "F") -> 1 | E24: =COUNTIFS('Treatment Record'!B:B,"Kamuli", 'Treatment Record'!I:I, "Ca") -> 2 | F24: =COUNTIFS('Treatment Record'!B:B,"Kamuli", 'Treatment Record'!I:I, "Ca/HIV") -> 0 | G24: =COUNTIFS('Treatment Record'!B:B,"Kamuli", 'Treatment Record'!I:I, "HIV") -> 0 | H24: =COUNTIFS('Treatment Record'!B:B,"Kamuli", 'Treatment Record'!I:I, "Other") -> 0 | I24: =SUMIFS('Treatment Record'!N:N, 'Treatment Record'!B:B, "Kamuli") -> 0 | J24: =SUMIFS('Treatment Record'!P:P, 'Treatment Record'!B:B, "Kamuli") -> 2 | K24: =SUMIFS('Treatment Record'!S:S, 'Treatment Record'!B:B, "Kamuli") -> 0 | L24: 0 | M24: =SUMIFS('Treatment Record'!T:T, 'Treatment Record'!B:B, "Kamuli") -> 0 | N24: 0
A25: Kayunga | B25: =COUNTIF('Treatment Record'!B:B,"Kayunga") -> 8 | C25: =COUNTIFS('Treatment Record'!B:B,"Kayunga", 'Treatment Record'!G:G, "M") -> 3 | D25: =COUNTIFS('Treatment Record'!B:B,"Kayunga", 'Treatment Record'!G:G, "F") -> 5 | E25: =COUNTIFS('Treatment Record'!B:B,"Kayunga", 'Treatment Record'!I:I, "Ca") -> 8 | F25: =COUNTIFS('Treatment Record'!B:B,"Kayunga", 'Treatment Record'!I:I, "Ca/HIV") -> 0 | G25: =COUNTIFS('Treatment Record'!B:B,"Kayunga", 'Treatment Record'!I:I, "HIV") -> 0 | H25: =COUNTIFS('Treatment Record'!B:B,"Kayunga", 'Treatment Record'!I:I, "Other") -> 0 | I25: =SUMIFS('Treatment Record'!N:N, 'Treatment Record'!B:B, "Kayunga") -> 2 | J25: =SUMIFS('Treatment Record'!P:P, 'Treatment Record'!B:B, "Kayunga") -> 6 | K25: =SUMIFS('Treatment Record'!S:S, 'Treatment Record'!B:B, "Kayunga") -> 1 | L25: 0 | M25: =SUMIFS('Treatment Record'!T:T, 'Treatment Record'!B:B, "Kayunga") -> 0 | N25: 0
A26: Kidera | B26: =COUNTIF('Treatment Record'!B:B,"Kidera") -> 1 | C26: =COUNTIFS('Treatment Record'!B:B,"Kidera", 'Treatment Record'!G:G, "M") -> 1 | D26: =COUNTIFS('Treatment Record'!B:B,"Kidera", 'Treatment Record'!G:G, "F") -> 0 | E26: =COUNTIFS('Treatment Record'!B:B,"Kidera", 'Treatment Record'!I:I, "Ca") -> 1 | F26: =COUNTIFS('Treatment Record'!B:B,"Kidera", 'Treatment Record'!I:I, "Ca/HIV") -> 0 | G26: =COUNTIFS('Treatment Record'!B:B,"Kidera", 'Treatment Record'!I:I, "HIV") -> 0 | H26: =COUNTIFS('Treatment Record'!B:B,"Kidera", 'Treatment Record'!I:I, "Other") -> 0 | I26: =SUMIFS('Treatment Record'!N:N, 'Treatment Record'!B:B, "Kidera") -> 0 | J26: =SUMIFS('Treatment Record'!P:P, 'Treatment Record'!B:B, "Kidera") -> 1 | K26: =SUMIFS('Treatment Record'!S:S, 'Treatment Record'!B:B, "Kidera") -> 0 | L26: 0 | M26: =SUMIFS('Treatment Record'!T:T, 'Treatment Record'!B:B, "Kidera") -> 0 | N26: 0
A27: Kiyindi | B27: =COUNTIF('Treatment Record'!B:B,"Kiyindi") -> 3 | C27: =COUNTIFS('Treatment Record'!B:B,"Kiyindi", 'Treatment Record'!G:G, "M") -> 1 | D27: =COUNTIFS('Treatment Record'!B:B,"Kiyindi", 'Treatment Record'!G:G, "F") -> 2 | E27: =COUNTIFS('Treatment Record'!B:B,"Kiyindi", 'Treatment Record'!I:I, "Ca") -> 2 | F27: =COUNTIFS('Treatment Record'!B:B,"Kiyindi", 'Treatment Record'!I:I, "Ca/HIV") -> 1 | G27: =COUNTIFS('Treatment Record'!B:B,"Kiyindi", 'Treatment Record'!I:I, "HIV") -> 0 | H27: =COUNTIFS('Treatment Record'!B:B,"Kiyindi", 'Treatment Record'!I:I, "Other") -> 0 | I27: =SUMIFS('Treatment Record'!N:N, 'Treatment Record'!B:B, "Kiyindi") -> 0 | J27: =SUMIFS('Treatment Record'!P:P, 'Treatment Record'!B:B, "Kiyindi") -> 3 | K27: =SUMIFS('Treatment Record'!S:S, 'Treatment Record'!B:B, "Kiyindi") -> 0 | L27: 0 | M27: =SUMIFS('Treatment Record'!T:T, 'Treatment Record'!B:B, "Kiyindi") -> 1 | N27: 0
A28: Kiyunga | B28: =COUNTIF('Treatment Record'!B:B,"Kiyunga") -> 1 | C28: =COUNTIFS('Treatment Record'!B:B,"Kiyunga", 'Treatment Record'!G:G, "M") -> 0 | D28: =COUNTIFS('Treatment Record'!B:B,"Kiyunga", 'Treatment Record'!G:G, "F") -> 1 | E28: =COUNTIFS('Treatment Record'!B:B,"Kiyunga", 'Treatment Record'!I:I, "Ca") -> 0 | F28: =COUNTIFS('Treatment Record'!B:B,"Kiyunga", 'Treatment Record'!I:I, "Ca/HIV") -> 1 | G28: =COUNTIFS('Treatment Record'!B:B,"Kiyunga", 'Treatment Record'!I:I, "HIV") -> 0 | H28: =COUNTIFS('Treatment Record'!B:B,"Kiyunga", 'Treatment Record'!I:I, "Other") -> 0 | I28: =SUMIFS('Treatment Record'!N:N, 'Treatment Record'!B:B, "Kiyunga") -> 0 | J28: =SUMIFS('Treatment Record'!P:P, 'Treatment Record'!B:B, "Kiyunga") -> 1 | K28: =SUMIFS('Treatment Record'!S:S, 'Treatment Record'!B:B, "Kiyunga") -> 0 | L28: 0 | M28: =SUMIFS('Treatment Record'!T:T, 'Treatment Record'!B:B, "Kiyunga") -> 0 | N28: 0
A29: Lumino | B29: =COUNTIF('Treatment Record'!B:B,"Lumino") -> 0 | C29: =COUNTIFS('Treatment Record'!B:B,"Lumino", 'Treatment Record'!G:G, "M") -> 0 | D29: =COUNTIFS('Treatment Record'!B:B,"Lumino", 'Treatment Record'!G:G, "F") -> 0 | E29: =COUNTIFS('Treatment Record'!B:B,"Lumino", 'Treatment Record'!I:I, "Ca") -> 0 | F29: =COUNTIFS('Treatment Record'!B:B,"Lumino", 'Treatment Record'!I:I, "Ca/HIV") -> 0 | G29: =COUNTIFS('Treatment Record'!B:B,"Lumino", 'Treatment Record'!I:I, "HIV") -> 0 | H29: =COUNTIFS('Treatment Record'!B:B,"Lumino", 'Treatment Record'!I:I, "Other") -> 0 | I29: =SUMIFS('Treatment Record'!N:N, 'Treatment Record'!B:B, "Lumino") -> 0 | J29: =SUMIFS('Treatment Record'!P:P, 'Treatment Record'!B:B, "Lumino") -> 0 | K29: =SUMIFS('Treatment Record'!S:S, 'Treatment Record'!B:B, "Lumino") -> 0 | L29: 0 | M29: =SUMIFS('Treatment Record'!T:T, 'Treatment Record'!B:B, "Lumino") -> 0 | N29: 0
A30: Makuutu | B30: =COUNTIF('Treatment Record'!B:B,"Makuutu") -> 0 | C30: =COUNTIFS('Treatment Record'!B:B,"Makuutu", 'Treatment Record'!G:G, "M") -> 0 | D30: =COUNTIFS('Treatment Record'!B:B,"Makuutu", 'Treatment Record'!G:G, "F") -> 0 | E30: =COUNTIFS('Treatment Record'!B:B,"Makuutu", 'Treatment Record'!I:I, "Ca") -> 0 | F30: =COUNTIFS('Treatment Record'!B:B,"Makuutu", 'Treatment Record'!I:I, "Ca/HIV") -> 0 | G30: =COUNTIFS('Treatment Record'!B:B,"Makuutu", 'Treatment Record'!I:I, "HIV") -> 0 | H30: =COUNTIFS('Treatment Record'!B:B,"Makuutu", 'Treatment Record'!I:I, "Other") -> 0 | I30: =SUMIFS('Treatment Record'!N:N, 'Treatment Record'!B:B, "Makuutu") -> 0 | J30: =SUMIFS('Treatment Record'!P:P, 'Treatment Record'!B:B, "Makuutu") -> 0 | K30: =SUMIFS('Treatment Record'!S:S, 'Treatment Record'!B:B, "Makuutu") -> 0 | L30: 0 | M30: =SUMIFS('Treatment Record'!T:T, 'Treatment Record'!B:B, "Makuutu") -> 0 | N30: 0
A31: Mayuge | B31: =COUNTIF('Treatment Record'!B:B,"Mayuge") -> 0 | C31: =COUNTIFS('Treatment Record'!B:B,"Mayuge", 'Treatment Record'!G:G, "M") -> 0 | D31: =COUNTIFS('Treatment Record'!B:B,"Mayuge", 'Treatment Record'!G:G, "F") -> 0 | E31: =COUNTIFS('Treatment Record'!B:B,"Mayuge", 'Treatment Record'!I:I, "Ca") -> 0 | F31: =COUNTIFS('Treatment Record'!B:B,"Mayuge", 'Treatment Record'!I:I, "Ca/HIV") -> 0 | G31: =COUNTIFS('Treatment Record'!B:B,"Mayuge", 'Treatment Record'!I:I, "HIV") -> 0 | H31: =COUNTIFS('Treatment Record'!B:B,"Mayuge", 'Treatment Record'!I:I, "Other") -> 0 | I31: =SUMIFS('Treatment Record'!N:N, 'Treatment Record'!B:B, "Mayuge") -> 0 | J31: =SUMIFS('Treatment Record'!P:P, 'Treatment Record'!B:B, "Mayuge") -> 0 | K31: =SUMIFS('Treatment Record'!S:S, 'Treatment Record'!B:B, "Mayuge") -> 0 | L31: 0 | M31: =SUMIFS('Treatment Record'!T:T, 'Treatment Record'!B:B, "Mayuge") -> 0 | N31: 0
A32: Mbulamuti | B32: =COUNTIF('Treatment Record'!B:B,"Mbulamuti") -> 3 | C32: =COUNTIFS('Treatment Record'!B:B,"Mbulamuti", 'Treatment Record'!G:G, "M") -> 1 | D32: =COUNTIFS('Treatment Record'!B:B,"Mbulamuti", 'Treatment Record'!G:G, "F") -> 2 | E32: =COUNTIFS('Treatment Record'!B:B,"Mbulamuti", 'Treatment Record'!I:I, "Ca") -> 2 | F32: =COUNTIFS('Treatment Record'!B:B,"Mbulamuti", 'Treatment Record'!I:I, "Ca/HIV") -> 0 | G32: =COUNTIFS('Treatment Record'!B:B,"Mubulamuti", 'Treatment Record'!I:I, "HIV") -> 0 | H32: =COUNTIFS('Treatment Record'!B:B,"Mbulamuti", 'Treatment Record'!I:I, "Other") -> 1 | I32: =SUMIFS('Treatment Record'!N:N, 'Treatment Record'!B:B, "Mbulamuti") -> 3 | J32: =SUMIFS('Treatment Record'!P:P, 'Treatment Record'!B:B, "Mbulamuti") -> 0 | K32: =SUMIFS('Treatment Record'!S:S, 'Treatment Record'!B:B, "Mbulamuti") -> 0 | L32: 0 | M32: 0 | N32: 0 | Q32: Diagnosis
A33: Muterere | B33: =COUNTIF('Treatment Record'!B:B,"Muterere") -> 1 | C33: =COUNTIFS('Treatment Record'!B:B,"Mutererei", 'Treatment Record'!G:G, "M") -> 0 | D33: =COUNTIFS('Treatment Record'!B:B,"Muterere", 'Treatment Record'!G:G, "F") -> 1 | E33: =COUNTIFS('Treatment Record'!B:B,"Muterere", 'Treatment Record'!I:I, "Ca") -> 1 | F33: =COUNTIFS('Treatment Record'!B:B,"Muterere", 'Treatment Record'!I:I, "Ca/HIV") -> 0 | G33: =COUNTIFS('Treatment Record'!B:B,"Muterere", 'Treatment Record'!I:I, "HIV") -> 0 | H33: =COUNTIFS('Treatment Record'!B:B,"Muterere", 'Treatment Record'!I:I, "Other") -> 0 | I33: =SUMIFS('Treatment Record'!N:N, 'Treatment Record'!B:B, "Muterere") -> 0 | J33: =SUMIFS('Treatment Record'!P:P, 'Treatment Record'!B:B, "Muterere") -> 1 | K33: =SUMIFS('Treatment Record'!S:S, 'Treatment Record'!B:B, "Muterere") -> 0 | L33: 0 | M33: 0 | N33: 0 | Q33: Ameloblastoma | R33: 1
A34: Namayingo | B34: =COUNTIF('Treatment Record'!B:B,"Namayingo") -> 8 | C34: =COUNTIFS('Treatment Record'!B:B,"Namayingo", 'Treatment Record'!G:G, "M") -> 2 | D34: =COUNTIFS('Treatment Record'!B:B,"Namayingo", 'Treatment Record'!G:G, "F") -> 6 | E34: =COUNTIFS('Treatment Record'!B:B,"Namayingo", 'Treatment Record'!I:I, "Ca") -> 7 | F34: =COUNTIFS('Treatment Record'!B:B,"Namayingo", 'Treatment Record'!I:I, "Ca/HIV") -> 0 | G34: =COUNTIFS('Treatment Record'!B:B,"Namayingo", 'Treatment Record'!I:I, "HIV") -> 0 | H34: =COUNTIFS('Treatment Record'!B:B,"Namayingo", 'Treatment Record'!I:I, "Other") -> 1 | I34: =SUMIFS('Treatment Record'!N:N, 'Treatment Record'!B:B, "Namayingo") -> 4 | J34: =SUMIFS('Treatment Record'!P:P, 'Treatment Record'!B:B, "Namayingo") -> 4 | K34: =SUMIFS('Treatment Record'!S:S, 'Treatment Record'!B:B, "Namayingo") -> 0 | L34: 0 | M34: =SUMIFS('Treatment Record'!T:T, 'Treatment Record'!B:B, "Namayingo") -> 3 | N34: 0 | Q34: Ca Breast | R34: 19
A35: Namasagali | B35: =COUNTIF('Treatment Record'!B:B,"Namasagali") -> 0 | C35: =COUNTIFS('Treatment Record'!B:B,"Namasagali", 'Treatment Record'!G:G, "M") -> 0 | D35: =COUNTIFS('Treatment Record'!B:B,"Namasagali", 'Treatment Record'!G:G, "F") -> 0 | E35: =COUNTIFS('Treatment Record'!B:B,"Namasagali", 'Treatment Record'!I:I, "Ca") -> 0 | F35: =COUNTIFS('Treatment Record'!B:B,"Namasagali", 'Treatment Record'!I:I, "Ca/HIV") -> 0 | G35: =COUNTIFS('Treatment Record'!B:B,"Namasagali", 'Treatment Record'!I:I, "HIV") -> 0 | H35: =COUNTIFS('Treatment Record'!B:B,"Namasagali", 'Treatment Record'!I:I, "Other") -> 0 | I35: =SUMIFS('Treatment Record'!N:N, 'Treatment Record'!B:B, "Namasagali") -> 0 | J35: =SUMIFS('Treatment Record'!P:P, 'Treatment Record'!B:B, "Namasagali") -> 0 | K35: =SUMIFS('Treatment Record'!S:S, 'Treatment Record'!B:B, "Namasagali") -> 0 | L35: 0 | M35: =SUMIFS('Treatment Record'!T:T, 'Treatment Record'!B:B, "Namasagali") -> 0 | N35: 0 | Q35: Ca Breast+HIV/AIDS | R35: 1
A36: Namungalwe | B36: =COUNTIF('Treatment Record'!B:B,"Namungalwe") -> 2 | C36: =COUNTIFS('Treatment Record'!B:B,"Namungalwe", 'Treatment Record'!G:G, "M") -> 1 | D36: =COUNTIFS('Treatment Record'!B:B,"Namungalwe", 'Treatment Record'!G:G, "F") -> 1 | E36: =COUNTIFS('Treatment Record'!B:B,"Namungalwe", 'Treatment Record'!I:I, "Ca") -> 2 | F36: =COUNTIFS('Treatment Record'!B:B,"Namungalwe", 'Treatment Record'!I:I, "Ca/HIV") -> 0 | G36: =COUNTIFS('Treatment Record'!B:B,"Namungalwe", 'Treatment Record'!I:I, "HIV") -> 0 | H36: =COUNTIFS('Treatment Record'!B:B,"Namungalwe", 'Treatment Record'!I:I, "Other") -> 0 | I36: =SUMIFS('Treatment Record'!N:N, 'Treatment Record'!B:B, "Namungalwe") -> 0 | J36: =SUMIFS('Treatment Record'!P:P, 'Treatment Record'!B:B, "Namungalwe") -> 2 | K36: =SUMIFS('Treatment Record'!S:S, 'Treatment Record'!B:B, "Namungalwe") -> 0 | L36: 0 | M36: =SUMIFS('Treatment Record'!T:T, 'Treatment Record'!B:B, "Namungalwe") -> 0 | N36: 0 | Q36: Ca Colon | R36: 1
A37: Namwendwa | B37: =COUNTIF('Treatment Record'!B:B,"Namwendwa") -> 1 | C37: =COUNTIFS('Treatment Record'!B:B,"Namwendwa", 'Treatment Record'!G:G, "M") -> 0 | D37: =COUNTIFS('Treatment Record'!B:B,"Namwendwa", 'Treatment Record'!G:G, "F") -> 1 | E37: =COUNTIFS('Treatment Record'!B:B,"Namwendwa", 'Treatment Record'!I:I, "Ca") -> 1 | F37: =COUNTIFS('Treatment Record'!B:B,"Namwendwa", 'Treatment Record'!I:I, "Ca/HIV") -> 0 | G37: =COUNTIFS('Treatment Record'!B:B,"Namwendwa", 'Treatment Record'!I:I, "HIV") -> 0 | H37: =COUNTIFS('Treatment Record'!B:B,"Namwendwa", 'Treatment Record'!I:I, "Other") -> 0 | I37: =SUMIFS('Treatment Record'!N:N, 'Treatment Record'!B:B, "Namwendwa") -> 1 | J37: =SUMIFS('Treatment Record'!P:P, 'Treatment Record'!B:B, "Namwendwa") -> 0 | K37: =SUMIFS('Treatment Record'!S:S, 'Treatment Record'!B:B, "Namwendwa") -> 0 | L37: 0 | M37: =SUMIFS('Treatment Record'!T:T, 'Treatment Record'!B:B, "Namwendwa") -> 0 | N37: 0 | Q37: Ca Penis | R37: 1
A38: Nawampiti/Buyengo | B38: =COUNTIF('Treatment Record'!B:B,"Nawampiti") -> 0 | C38: =COUNTIFS('Treatment Record'!B:B,"Nawampiti", 'Treatment Record'!G:G, "M") -> 0 | D38: =COUNTIFS('Treatment Record'!B:B,"Nawampiti", 'Treatment Record'!G:G, "F") -> 0 | E38: =COUNTIFS('Treatment Record'!B:B,"Nawampiti", 'Treatment Record'!I:I, "Ca") -> 0 | F38: =COUNTIFS('Treatment Record'!B:B,"Nawampiti", 'Treatment Record'!I:I, "Ca/HIV") -> 0 | G38: =COUNTIFS('Treatment Record'!B:B,"Nawampiti", 'Treatment Record'!I:I, "HIV") -> 0 | H38: =COUNTIFS('Treatment Record'!B:B,"Nawampiti", 'Treatment Record'!I:I, "Other") -> 0 | I38: =SUMIFS('Treatment Record'!N:N, 'Treatment Record'!B:B, "Nawampiti") -> 0 | J38: =SUMIFS('Treatment Record'!P:P, 'Treatment Record'!B:B, "Nawampiti") -> 0 | K38: =SUMIFS('Treatment Record'!S:S, 'Treatment Record'!B:B, "Nawampiti") -> 0 | L38: 0 | M38: =SUMIFS('Treatment Record'!T:T, 'Treatment Record'!B:B, "Nawampiti") -> 0 | N38: 0 | Q38: Ca Prostate | R38: 5
A39: Nawanyago | B39: =COUNTIF('Treatment Record'!B:B,"Nawanyago") -> 2 | C39: =COUNTIFS('Treatment Record'!B:B,"Nawanyago", 'Treatment Record'!G:G, "M") -> 0 | D39: =COUNTIFS('Treatment Record'!B:B,"Nawanyago", 'Treatment Record'!G:G, "F") -> 2 | E39: =COUNTIFS('Treatment Record'!B:B,"Nawanyago", 'Treatment Record'!I:I, "Ca") -> 2 | F39: =COUNTIFS('Treatment Record'!B:B,"Nawanyago", 'Treatment Record'!I:I, "Ca/HIV") -> 0 | G39: =COUNTIFS('Treatment Record'!B:B,"Nawanyago", 'Treatment Record'!I:I, "HIV") -> 0 | H39: =COUNTIFS('Treatment Record'!B:B,"Nawanyago", 'Treatment Record'!I:I, "Other") -> 0 | I39: =SUMIFS('Treatment Record'!N:N, 'Treatment Record'!B:B, "Nawanyago") -> 0 | J39: =SUMIFS('Treatment Record'!P:P, 'Treatment Record'!B:B, "Nawanyago") -> 2 | K39: =SUMIFS('Treatment Record'!S:S, 'Treatment Record'!B:B, "Nawanyago") -> 0 | L39: 0 | M39: =SUMIFS('Treatment Record'!T:T, 'Treatment Record'!B:B, "Nawanyago") -> 0 | N39: 0 | Q39: Ca Rectum | R39: 2
A40: Nyenga | B40: =COUNTIF('Treatment Record'!B:B,"Nyenga") -> 0 | C40: =COUNTIFS('Treatment Record'!B:B,"Nyenga", 'Treatment Record'!G:G, "M") -> 0 | D40: =COUNTIFS('Treatment Record'!B:B,"Nyenga", 'Treatment Record'!G:G, "F") -> 0 | E40: =COUNTIFS('Treatment Record'!B:B,"Nyenga", 'Treatment Record'!I:I, "Ca") -> 0 | F40: =COUNTIFS('Treatment Record'!B:B,"Nyenga", 'Treatment Record'!I:I, "Ca/HIV") -> 0 | G40: =COUNTIFS('Treatment Record'!B:B,"Nyenga", 'Treatment Record'!I:I, "HIV") -> 0 | H40: =COUNTIFS('Treatment Record'!B:B,"Nyenga", 'Treatment Record'!I:I, "Other") -> 0 | I40: =SUMIFS('Treatment Record'!N:N, 'Treatment Record'!B:B, "Nyenga") -> 0 | J40: =SUMIFS('Treatment Record'!P:P, 'Treatment Record'!B:B, "Nyenga") -> 0 | K40: =SUMIFS('Treatment Record'!S:S, 'Treatment Record'!B:B, "Nyenga") -> 0 | L40: 0 | M40: =SUMIFS('Treatment Record'!T:T, 'Treatment Record'!B:B, "Nyenga") -> 0 | N40: 0 | Q40: Ca Testacles | R40: 1
...

Sheet Monthly Summary
A1: Year | B1: Month | C1: Total | D1: M | E1: F | F1: Ca | G1: Ca/HIV | H1: HIV | I1: Others | J1: New | K1: Old appts | L1: Discharg | M1: RIP
A2: 2020 | B2: January | C2: 40 | D2: 14 | E2: 26 | F2: 32 | G2: 6 | H2: 0 | I2: 2 | J2: 15 | K2: 25 | L2: 0 | M2: 0
B3: February | C3: 39 | D3: 17 | E3: 22 | F3: 31 | G3: 4 | H3: 0 | I3: 4 | J3: 14 | K3: 25 | L3: 0 | M3: 0
B4: March | C4: 36 | D4: 15 | E4: 21 | F4: 29 | G4: 3 | H4: 1 | I4: 3 | J4: 5 | K4: 31 | L4: 0 | M4: 5
B6: April | C6: 14 | D6: 7 | E6: 7 | F6: 12 | G6: 1 | H6: 0 | I6: 1 | J6: 0 | K6: 14 | L6: 0 | M6: 1
B7: May | C7: 11 | D7: 5 | E7: 6 | F7: 10 | G7: 0 | H7: 0 | I7: 1 | J7: 1 | K7: 10 | L7: 0 | M7: 0
B8: June | C8: 24 | D8: 10 | E8: 14 | F8: 15 | G8: 3 | H8: 0 | I8: 6 | J8: 10 | K8: 14 | L8: 0 | M8: 0
B10: July | C10: 28 | D10: 12 | E10: 16 | F10: 23 | G10: 2 | H10: 0 | I10: 3 | J10: 0 | K10: 25 | L10: 1 | M10: 1
B11: August | C11: 32 | D11: 9 | E11: 23 | F11: 25 | G11: 3 | H11: 0 | I11: 4 | J11: 13 | K11: 18 | L11: 0 | M11: 0
B12: September | C12: 20 | D12: 8 | E12: 12 | F12: 16 | G12: 3 | H12: 0 | I12: 2 | J12: 6 | K12: 14 | L12: 0 | M12: 3
B14: October | C14: 39 | D14: 14 | E14: 25 | F14: 25 | G14: 6 | H14: 1 | I14: 7 | J14: 14 | K14: 25 | L14: 0 | M14: 2
B15: November | C15: 43 | D15: 17 | E15: 26 | F15: 28 | G15: 6 | H15: 1 | I15: 7 | J15: 14 | K15: 29 | L15: 1 | M15: 3
B16: December | C16: 19 | D16: 5 | E16: 14 | F16: 13 | G16: 3 | H16: 0 | I16: 3 | J16: 2 | K16: 18 | L16: 0 | M16: 2
D17: =SUM(D2:D16) -> 133 | E17: =SUM(E2:E16) -> 212 | J17: =SUM(J2:J16) -> 94
E19: Number of patients supported 2020 | I19: 119
A21: 2021 | B21: January | C21: 22 | D21: 7 | E21: 14 | F21: 15 | G21: 2 | H21: 1 | I21: 1 | J21: 1 | K21: 16 | L21: 0 | M21: 0
B22: February | C22: 37 | D22: 15 | E22: 22 | F22: 28 | G22: 4 | H22: 0 | I22: 5 | J22: 12 | K22: 25 | L22: 0 | M22: 0
B23: March | C23: 43 | D23: 13 | E23: 30 | F23: 29 | G23: 6 | H23: 0 | I23: 8 | J23: 14 | K23: 29 | L23: 0 | M23: 0
B25: April | C25: 43 | D25: 12 | E25: 31 | F25: 25 | G25: 2 | H25: 1 | I25: 15 | J25: 10 | K25: 33 | L25: 0 | M25: 1
B26: May | C26: 42 | D26: 13 | E26: 29 | F26: 32 | G26: 4 | H26: 0 | I26: 5 | J26: 15 | K26: 27 | L26: 0 | M26: 3
B27: June | C27: 45 | D27: 9 | E27: 36 | F27: 37 | G27: 4 | H27: 1 | I27: 3 | J27: 14 | K27: 31 | L27: 0 | M27: 2
B29: July | C29: 44 | D29: 15 | E29: 29 | F29: 36 | G29: 6 | H29: 0 | I29: 2 | J29: 6 | K29: 38 | L29: 0 | M29: 0
B30: August | C30: 37 | D30: 11 | E30: 26 | F30: 30 | G30: 6 | H30: 0 | I30: 1 | J30: 10 | K30: 26 | L30: 1 | M30: 0
B31: September | C31: 63 | D31: 20 | E31: 43 | F31: 48 | G31: 7 | H31: 0 | I31: 8 | J31: 8 | K31: 55 | L31: 2 | M31: 0
B33: October | C33: 55 | D33: 13 | E33: 42 | F33: 45 | G33: 8 | H33: 0 | I33: 2 | J33: 26 | K33: 29 | L33: 0 | M33: 0
B34: November | C34: 84 | D34: 27 | E34: 57 | F34: 69 | G34: 8 | H34: 0 | I34: 7 | J34: 27 | K34: 57 | L34: 0 | M34: 5
B35: December | C35: 47 | D35: 10 | E35: 37 | F35: 37 | G35: 4 | H35: 0 | I35: 6 | J35: 12 | K35: 35 | L35: 0 | M35: 2
J36: =SUM(J21:J35) -> 155
A39: 2022 | B39: January | C39: 30 | D39: 8 | E39: 22 | F39: 21 | G39: 3 | H39: 0 | I39: 4 | J39: 10 | K39: 20 | L39: 0 | M39: 0
B40: February | C40: 58 | D40: 23 | E40: 35 | F40: 45 | G40: 6 | H40: 0 | I40: 7 | J40: 11 | K40: 47 | L40: 1 | M40: 0
B41: March | C41: 78 | D41: 27 | E41: 51 | F41: 59 | G41: 8 | H41: 1 | I41: 10 | J41: 13 | K41: 65 | L41: 1 | M41: 3
B43: April | C43: 48 | D43: 19 | E43: 29 | F43: 40 | G43: 4 | H43: 0 | I43: 4 | J43: 8 | K43: 40 | L43: 0 | M43: 1
B44: May | C44: 60 | D44: 30 | E44: 30 | F44: 48 | G44: 5 | H44: 0 | I44: 7 | J44: 14 | K44: 46 | L44: 0 | M44: 2
B45: June | C45: 66 | D45: 27 | E45: 39 | F45: 46 | G45: 7 | H45: 2 | I45: 11 | J45: 13 | K45: 54 | L45: 0 | M45: 0
B47: July | C47: 68 | D47: 20 | E47: 48 | F47: 47 | G47: 6 | H47: 4 | I47: 11 | J47: 18 | K47: 50 | L47: 0 | M47: 4
B48: August | C48: 68 | D48: 26 | E48: 42 | F48: 50 | G48: 7 | H48: 0 | I48: 11 | J48: 13 | K48: 55 | L48: 0 | M48: 1
B49: September | C49: 68 | D49: 26 | E49: 42 | F49: 48 | G49: 8 | H49: 1 | I49: 11 | J49: 9 | K49: 59 | L49: 0 | M49: 2
B51: October | C51: 49 | D51: 16 | E51: 33 | F51: 30 | G51: 7 | H51: 3 | I51: 9 | J51: 11 | K51: 38 | L51: 0 | M51: 1
B52: November | C52: 66 | D52: 27 | E52: 38 | F52: 41 | G52: 9 | H52: 0 | I52: 15 | J52: 16 | K52: 50 | L52: 0 | M52: 2
B53: December | C53: 38 | D53: 17 | E53: 21 | F53: 27 | G53: 5 | H53: 1 | I53: 5 | J53: 6 | K53: 32 | L53: 1 | M53: 2
...
